Workbook

Sheet 요약_2025.12
A1: 해외 은행 자회사 순자산 기회비용 – 벤치마크 금리 요약 (최상위 은행채 3년, 현지통화)
A3: 기준월 | B3: 45992 | C3: ← 변경 가능 (노란 셀)
A4: 기준분기 | B4: =YEAR(B3)&"Q"&ROUNDUP(MONTH(B3)/3,0) -> 2025Q4 | C4: 베트남 은행채(발행 희소)는 기준분기 발행액 가중값을 사용
A6: 국가 | B6: 통화 | C6: 정책금리 (기준월말) | D6: 국채 3Y (기준월 평균) | E6: 벤치마크 지표 | F6: 은행채/회사채 수익률 | G6: 스프레드 (bp) | H6: 권고 벤치마크 (세전) =국채+스프레드 | I6: 법인세율 (입력) | J6: 세후 환산 | K6: 측정창 | L6: 비고
A7: 일본 | B7: JPY | C7: =INDEX(월별!$E$5:$E$70,MATCH($B$3,월별!$A$5:$A$70,0)) -> 0.0075 | D7: =INDEX(월별!$F$5:$F$70,MATCH($B$3,월별!$A$5:$A$70,0)) -> 0.011856818 | E7: 일본 회사채 R&I AA 잔존 3년 평균 (JSDA 格付マトリクス) | F7: =IFERROR(INDEX(월별!$G$5:$G$70,MATCH($B$3,월별!$A$5:$A$70,0)),"") -> 0.015895 | G7: =IFERROR((INDEX(월별!$G$5:$G$70,MATCH($B$3,월별!$A$5:$A$70,0))-INDEX(월별!$F$5:$F$70,MATCH($B$3,월별!$A$5:$A$70,0)))*10000,"") -> 40.381818 | H7: =IFERROR(D7+G7/10000,"") -> 0.015895 | I7: 0.3062 | J7: =IFERROR(H7*(1-I7),"") -> 0.011027951 | K7: 기준월 평균 | L7: JSDA 등급별 매트릭스는 전 업종 회사채 기준(은행 한정 아님). 메가뱅크 국내 등급(R&I)은 대체로 A+~AA- 수준. AAA는 표본 3~5종목으로 적어 참고용(월별 시트 H열). 법인세율은 대기업 법정실효세율 가정.
A8: 중국 | B8: CNY | C8: =INDEX(월별!$J$5:$J$70,MATCH($B$3,월별!$A$5:$A$70,0)) -> 0.03 | D8: =INDEX(월별!$K$5:$K$70,MATCH($B$3,월별!$A$5:$A$70,0)) -> 0.014045217 | E8: 中债 商业银行普通债(AAA) 3년 (ChinaBond) | F8: =IFERROR(INDEX(월별!$L$5:$L$70,MATCH($B$3,월별!$A$5:$A$70,0)),"") -> 0.018408 | G8: =IFERROR((INDEX(월별!$L$5:$L$70,MATCH($B$3,월별!$A$5:$A$70,0))-INDEX(월별!$K$5:$K$70,MATCH($B$3,월별!$A$5:$A$70,0)))*10000,"") -> 43.627826 | H8: =IFERROR(D8+G8/10000,"") -> 0.018408 | I8: 0.25 | J8: =IFERROR(H8*(1-I8),"") -> 0.013806 | K8: 기준월 평균 | L8: 은행 선순위 일반채 AAA 커브 직접 사용. 정책금리 열은 LPR 1Y(BIS 기준). 국채 이자 비과세 vs 금융채 과세 차이가 스프레드에 일부 포함. 2025.8.8 이후 신규 금융채 이자 VAT 부과.
A9: 베트남 (권고) | B9: VND | C9: =INDEX(월별!$O$5:$O$70,MATCH($B$3,월별!$A$5:$A$70,0)) -> 0.045 | D9: =INDEX(월별!$P$5:$P$70,MATCH($B$3,월별!$A$5:$A$70,0)) -> 0.031686957 | E9: Big4(국영) 선순위 고정금리 은행채 발행 스프레드 (VBMA) | F9: =IFERROR(D9+G9/10000,"") -> 0.058486957 | G9: =IFERROR(INDEX(분기·연도별!$S$5:$S$40,MATCH($B$4,분기·연도별!$A$5:$A$40,0)),"") -> 268 | H9: =IFERROR(D9+G9/10000,"") -> 0.058486957 | I9: 0.2 | J9: =IFERROR(H9*(1-I9),"") -> 0.046789565 | K9: 국채: 기준월 / 스프레드: 기준분기 | L9: Big4 고정금리 선순위 발행은 매우 드묾(2025.4Q: Vietcombank 2년물 5.8%, 2025.12.18 1건). Big4는 대부분 변동금리(12개월 예금금리+α) 후순위성 장기채 발행 → 표본 제약 명시 필요.
A10: 베트남 (참고) | B10: VND | C10: =INDEX(월별!$O$5:$O$70,MATCH($B$3,월별!$A$5:$A$70,0)) -> 0.045 | D10: =INDEX(월별!$P$5:$P$70,MATCH($B$3,월별!$A$5:$A$70,0)) -> 0.031686957 | E10: 은행 전체 선순위 고정 2~4년 발행 스프레드 (VBMA) | F10: =IFERROR(D10+G10/10000,"") -> 0.066682796 | G10: =IFERROR(INDEX(분기·연도별!$Q$5:$Q$40,MATCH($B$4,분기·연도별!$A$5:$A$40,0)),"") -> 349.9584 | H10: =IFERROR(D10+G10/10000,"") -> 0.066682796 | I10: 0.2 | J10: =IFERROR(H10*(1-I10),"") -> 0.053346237 | K10: 국채: 기준월 / 스프레드: 기준분기 | L10: 민간은행(Techcombank, VPBank, VIB, OCB, HDBank 등) 중심 → 최상위 등급보다 높게 나옴. 하한(최상위)과 범위 확인용.
A11: 카자흐스탄 | B11: KZT | C11: =INDEX(월별!$V$5:$V$70,MATCH($B$3,월별!$A$5:$A$70,0)) -> 0.18 | D11: =INDEX(월별!$W$5:$W$70,MATCH($B$3,월별!$A$5:$A$70,0)) -> 0.16561364 | E11: KASE 회사채 수익률지수 KASE_BMY (주시장 회사채) | F11: =IFERROR(INDEX(월별!$Y$5:$Y$70,MATCH($B$3,월별!$A$5:$A$70,0)),"") -> 0.16829091 | G11: =IFERROR((INDEX(월별!$Y$5:$Y$70,MATCH($B$3,월별!$A$5:$A$70,0))-INDEX(월별!$W$5:$W$70,MATCH($B$3,월별!$A$5:$A$70,0)))*10000,"") -> 26.772727 | H11: =IFERROR(MAX(D11,F11),"") -> 0.16829091 | I11: 0.2 | J11: =IFERROR(H11*(1-I11),"") -> 0.13463273 | K11: 기준월 평균 | L11: 권고값 = MAX(국채, 회사채지수): KZT 우량 회사채는 준국영 발행 위주라 국채와 비슷하거나 낮게 거래됨(2022~23년, 2025년 2~3분기 스프레드 음수) → 하한 취지에 맞게 큰 값 적용. 국채는 KASE 정부채 수익률지수(잔존 1~5년). 은행채 개별 거래 희소(Halyk KZT채 2025.4Q 거래 없음) → 회사채 지수 사용. 2026.4부터 BBB- 이상 회사채 지표(KASE_KZ3_Y, 듀레이션 약 2.7년) 제공 → 향후 대체 권고.
A13: 읽는 법
A14: • 권고 벤치마크 = 국채 3년(기준월 평균) + 최상위 은행채(회사채) 스프레드. 중국·일본은 은행채(회사채) 수익률과 같은 값, 베트남은 발행 희소로 스프레드를 분기 단위로 측정해 국채에 더함, 카자흐는 국채와 회사채지수 중 큰 값.
A15: • 세후 환산은 비교 대상 이익이 세후(당기순이익)일 때 사용. 법인세율(노란 셀)은 가정치이므로 각 법인 실효세율로 바꿔 쓰세요.
A16: • 2021~2026.6 추이는 「월별」, 「분기·연도별」 시트. 원자료는 각 일별 시트와 「VN_은행채발행」 시트(건별, 필터 사용 가능).
A17: • 색 구분: 파란 글씨 = 원자료/입력값, 초록 글씨 = 다른 시트 참조 수식, 검정 = 계산 수식, 노란 칸 = 기준월·핵심 결과·입력 가정.

Sheet 월별
A1: 월별 시계열 (2021.01 ~ 2026.06) – 국채 3Y · 최상위 은행채(회사채) 3Y · 스프레드 · 정책금리
A2: 수익률: 월중 영업일 단순평균(일별 시트 참조). 정책금리: 월말값. 스프레드 = 은행채(회사채) − 국채 (bp). 베트남 은행채 = 해당월 발행 선순위 고정금리 2~4년물 발행액 가중평균(발행 없는 달은 공란).
E3: 일본 (JPY) | J3: 중국 (CNY) | O3: 베트남 (VND) | V3: 카자흐스탄 (KZT)
A4: 월 | B4: 월말 | C4: 분기 | D4: 연도 | E4: 정책금리 (월말) | F4: JGB 3Y | G4: 회사채 R&I AA 잔존3Y | H4: 회사채 R&I AAA 잔존3Y(참고) | I4: 스프레드 AA−JGB | J4: LPR 1Y (월말) | K4: 국채 3Y | L4: 상업은행채 AAA 3Y | M4: MTN AAA 3Y (참고) | N4: 스프레드 은행AAA−국채 | O4: 재할인율 (월말) | P4: VGB 3Y | Q4: 은행채 발행금리 선순위고정2~4Y (가중) | R4: 발행 건수 | S4: 스프레드 (동일만기 국채대비, 가중) | T4: Big4 선순위 고정 발행금리 (가중) | U4: Big4 스프레드 | V4: 기준금리 (월말) | W4: 국채지수 1~5Y | X4: 국채 3Y (WGB,참고) | Y4: 회사채지수 KASE_BMY | Z4: BBB-이상 회사채 KASE_KZ3_Y | AA4: 스프레드 BMY−국채1~5Y | AB4: TONIA (월평균)
A5: 44197 | B5: =EOMONTH(A5,0) -> 44227 | C5: =YEAR(A5)&"Q"&ROUNDUP(MONTH(A5)/3,0) -> 2021Q1 | D5: =YEAR(A5) -> 2021 | E5: =LOOKUP($B5,정책금리_결정!$A$4:$A$70,정책금리_결정!$B$4:$B$70) -> -0.001 | F5: =IFERROR(AVERAGEIFS(JP_국채일별!$C$4:$C$1345,JP_국채일별!$A$4:$A$1345,">="&$A5,JP_국채일별!$A$4:$A$1345,"<="&$B5),"") -> -0.0012768421 | G5: =IFERROR(AVERAGEIFS(JP_등급별회사채!$D$4:$D$158,JP_등급별회사채!$A$4:$A$158,">="&$A5,JP_등급별회사채!$A$4:$A$158,"<="&$B5),"") -> 0.0013590909 | H5: =IFERROR(AVERAGEIFS(JP_등급별회사채!$B$4:$B$158,JP_등급별회사채!$A$4:$A$158,">="&$A5,JP_등급별회사채!$A$4:$A$158,"<="&$B5),"") -> 0.0014290909 | I5: =IF(OR(G5="",F5=""),"",(G5-F5)*10000) -> 26.35933 | J5: =LOOKUP($B5,정책금리_결정!$D$4:$D$70,정책금리_결정!$E$4:$E$70) -> 0.0385 | K5: =IFERROR(AVERAGEIFS(CN_일별!$B$4:$B$1372,CN_일별!$A$4:$A$1372,">="&$A5,CN_일별!$A$4:$A$1372,"<="&$B5),"") -> 0.02802725 | L5: =IFERROR(AVERAGEIFS(CN_일별!$C$4:$C$1372,CN_일별!$A$4:$A$1372,">="&$A5,CN_일별!$A$4:$A$1372,"<="&$B5),"") -> 0.03343065 | M5: =IFERROR(AVERAGEIFS(CN_일별!$D$4:$D$1372,CN_일별!$A$4:$A$1372,">="&$A5,CN_일별!$A$4:$A$1372,"<="&$B5),"") -> 0.0352797 | N5: =IF(OR(L5="",K5=""),"",(L5-K5)*10000) -> 54.034 | O5: =LOOKUP($B5,정책금리_결정!$G$4:$G$9,정책금리_결정!$H$4:$H$9) -> 0.04 | P5: =IFERROR(AVERAGEIFS(VN_국채일별!$D$4:$D$1436,VN_국채일별!$A$4:$A$1436,">="&$A5,VN_국채일별!$A$4:$A$1436,"<="&$B5),"") -> 0.0057809524 | Q5: =IFERROR(SUMIFS(VN_은행채발행!$T$4:$T$712,VN_은행채발행!$C$4:$C$712,$A5)/SUMIFS(VN_은행채발행!$I$4:$I$712,VN_은행채발행!$C$4:$C$712,$A5,VN_은행채발행!$S$4:$S$712,1),"") | R5: =COUNTIFS(VN_은행채발행!$C$4:$C$712,$A5,VN_은행채발행!$S$4:$S$712,1) -> 0 | S5: =IFERROR(SUMIFS(VN_은행채발행!$U$4:$U$712,VN_은행채발행!$C$4:$C$712,$A5)/SUMIFS(VN_은행채발행!$Y$4:$Y$712,VN_은행채발행!$C$4:$C$712,$A5),"") | T5: =IFERROR(SUMIFS(VN_은행채발행!$W$4:$W$712,VN_은행채발행!$C$4:$C$712,$A5)/SUMIFS(VN_은행채발행!$I$4:$I$712,VN_은행채발행!$C$4:$C$712,$A5,VN_은행채발행!$V$4:$V$712,1),"") | U5: =IFERROR(SUMIFS(VN_은행채발행!$X$4:$X$712,VN_은행채발행!$C$4:$C$712,$A5)/SUMIFS(VN_은행채발행!$Z$4:$Z$712,VN_은행채발행!$C$4:$C$712,$A5),"") | V5: =LOOKUP($B5,정책금리_결정!$J$4:$J$49,정책금리_결정!$K$4:$K$49) -> 0.09 | W5: =IFERROR(AVERAGEIFS(KZ_일별!$C$4:$C$1352,KZ_일별!$A$4:$A$1352,">="&$A5,KZ_일별!$A$4:$A$1352,"<="&$B5),"") | X5: =IFERROR(AVERAGEIFS(KZ_일별!$E$4:$E$1352,KZ_일별!$A$4:$A$1352,">="&$A5,KZ_일별!$A$4:$A$1352,"<="&$B5),"") | Y5: =IFERROR(AVERAGEIFS(KZ_일별!$F$4:$F$1352,KZ_일별!$A$4:$A$1352,">="&$A5,KZ_일별!$A$4:$A$1352,"<="&$B5),"") -> 0.10767222 | Z5: =IFERROR(AVERAGEIFS(KZ_일별!$G$4:$G$1352,KZ_일별!$A$4:$A$1352,">="&$A5,KZ_일별!$A$4:$A$1352,"<="&$B5),"") | AA5: =IF(OR(Y5="",W5=""),"",(Y5-W5)*10000) | AB5: =IFERROR(AVERAGEIFS(KZ_일별!$H$4:$H$1352,KZ_일별!$A$4:$A$1352,">="&$A5,KZ_일별!$A$4:$A$1352,"<="&$B5),"") -> 0.0822
A6: 44228 | B6: =EOMONTH(A6,0) -> 44255 | C6: =YEAR(A6)&"Q"&ROUNDUP(MONTH(A6)/3,0) -> 2021Q1 | D6: =YEAR(A6) -> 2021 | E6: =LOOKUP($B6,정책금리_결정!$A$4:$A$70,정책금리_결정!$B$4:$B$70) -> -0.001 | F6: =IFERROR(AVERAGEIFS(JP_국채일별!$C$4:$C$1345,JP_국채일별!$A$4:$A$1345,">="&$A6,JP_국채일별!$A$4:$A$1345,"<="&$B6),"") -> -0.001225 | G6: =IFERROR(AVERAGEIFS(JP_등급별회사채!$D$4:$D$158,JP_등급별회사채!$A$4:$A$158,">="&$A6,JP_등급별회사채!$A$4:$A$158,"<="&$B6),"") -> 0.0014 | H6: =IFERROR(AVERAGEIFS(JP_등급별회사채!$B$4:$B$158,JP_등급별회사채!$A$4:$A$158,">="&$A6,JP_등급별회사채!$A$4:$A$158,"<="&$B6),"") -> 0.001412 | I6: =IF(OR(G6="",F6=""),"",(G6-F6)*10000) -> 26.25 | J6: =LOOKUP($B6,정책금리_결정!$D$4:$D$70,정책금리_결정!$E$4:$E$70) -> 0.0385 | K6: =IFERROR(AVERAGEIFS(CN_일별!$B$4:$B$1372,CN_일별!$A$4:$A$1372,">="&$A6,CN_일별!$A$4:$A$1372,"<="&$B6),"") -> 0.028913588 | L6: =IFERROR(AVERAGEIFS(CN_일별!$C$4:$C$1372,CN_일별!$A$4:$A$1372,">="&$A6,CN_일별!$A$4:$A$1372,"<="&$B6),"") -> 0.034555294 | M6: =IFERROR(AVERAGEIFS(CN_일별!$D$4:$D$1372,CN_일별!$A$4:$A$1372,">="&$A6,CN_일별!$A$4:$A$1372,"<="&$B6),"") -> 0.037010529 | N6: =IF(OR(L6="",K6=""),"",(L6-K6)*10000) -> 56.417059 | O6: =LOOKUP($B6,정책금리_결정!$G$4:$G$9,정책금리_결정!$H$4:$H$9) -> 0.04 | P6: =IFERROR(AVERAGEIFS(VN_국채일별!$D$4:$D$1436,VN_국채일별!$A$4:$A$1436,">="&$A6,VN_국채일별!$A$4:$A$1436,"<="&$B6),"") -> 0.0068425 | Q6: =IFERROR(SUMIFS(VN_은행채발행!$T$4:$T$712,VN_은행채발행!$C$4:$C$712,$A6)/SUMIFS(VN_은행채발행!$I$4:$I$712,VN_은행채발행!$C$4:$C$712,$A6,VN_은행채발행!$S$4:$S$712,1),"") | R6: =COUNTIFS(VN_은행채발행!$C$4:$C$712,$A6,VN_은행채발행!$S$4:$S$712,1) -> 0 | S6: =IFERROR(SUMIFS(VN_은행채발행!$U$4:$U$712,VN_은행채발행!$C$4:$C$712,$A6)/SUMIFS(VN_은행채발행!$Y$4:$Y$712,VN_은행채발행!$C$4:$C$712,$A6),"") | T6: =IFERROR(SUMIFS(VN_은행채발행!$W$4:$W$712,VN_은행채발행!$C$4:$C$712,$A6)/SUMIFS(VN_은행채발행!$I$4:$I$712,VN_은행채발행!$C$4:$C$712,$A6,VN_은행채발행!$V$4:$V$712,1),"") | U6: =IFERROR(SUMIFS(VN_은행채발행!$X$4:$X$712,VN_은행채발행!$C$4:$C$712,$A6)/SUMIFS(VN_은행채발행!$Z$4:$Z$712,VN_은행채발행!$C$4:$C$712,$A6),"") | V6: =LOOKUP($B6,정책금리_결정!$J$4:$J$49,정책금리_결정!$K$4:$K$49) -> 0.09 | W6: =IFERROR(AVERAGEIFS(KZ_일별!$C$4:$C$1352,KZ_일별!$A$4:$A$1352,">="&$A6,KZ_일별!$A$4:$A$1352,"<="&$B6),"") | X6: =IFERROR(AVERAGEIFS(KZ_일별!$E$4:$E$1352,KZ_일별!$A$4:$A$1352,">="&$A6,KZ_일별!$A$4:$A$1352,"<="&$B6),"") | Y6: =IFERROR(AVERAGEIFS(KZ_일별!$F$4:$F$1352,KZ_일별!$A$4:$A$1352,">="&$A6,KZ_일별!$A$4:$A$1352,"<="&$B6),"") -> 0.107155 | Z6: =IFERROR(AVERAGEIFS(KZ_일별!$G$4:$G$1352,KZ_일별!$A$4:$A$1352,">="&$A6,KZ_일별!$A$4:$A$1352,"<="&$B6),"") | AA6: =IF(OR(Y6="",W6=""),"",(Y6-W6)*10000) | AB6: =IFERROR(AVERAGEIFS(KZ_일별!$H$4:$H$1352,KZ_일별!$A$4:$A$1352,">="&$A6,KZ_일별!$A$4:$A$1352,"<="&$B6),"") -> 0.08711
A7: 44256 | B7: =EOMONTH(A7,0) -> 44286 | C7: =YEAR(A7)&"Q"&ROUNDUP(MONTH(A7)/3,0) -> 2021Q1 | D7: =YEAR(A7) -> 2021 | E7: =LOOKUP($B7,정책금리_결정!$A$4:$A$70,정책금리_결정!$B$4:$B$70) -> -0.001 | F7: =IFERROR(AVERAGEIFS(JP_국채일별!$C$4:$C$1345,JP_국채일별!$A$4:$A$1345,">="&$A7,JP_국채일별!$A$4:$A$1345,"<="&$B7),"") -> -0.00128 | G7: =IFERROR(AVERAGEIFS(JP_등급별회사채!$D$4:$D$158,JP_등급별회사채!$A$4:$A$158,">="&$A7,JP_등급별회사채!$A$4:$A$158,"<="&$B7),"") -> 0.001355 | H7: =IFERROR(AVERAGEIFS(JP_등급별회사채!$B$4:$B$158,JP_등급별회사채!$A$4:$A$158,">="&$A7,JP_등급별회사채!$A$4:$A$158,"<="&$B7),"") -> 0.0012125 | I7: =IF(OR(G7="",F7=""),"",(G7-F7)*10000) -> 26.35 | J7: =LOOKUP($B7,정책금리_결정!$D$4:$D$70,정책금리_결정!$E$4:$E$70) -> 0.0385 | K7: =IFERROR(AVERAGEIFS(CN_일별!$B$4:$B$1372,CN_일별!$A$4:$A$1372,">="&$A7,CN_일별!$A$4:$A$1372,"<="&$B7),"") -> 0.029181 | L7: =IFERROR(AVERAGEIFS(CN_일별!$C$4:$C$1372,CN_일별!$A$4:$A$1372,">="&$A7,CN_일별!$A$4:$A$1372,"<="&$B7),"") -> 0.034136304 | M7: =IFERROR(AVERAGEIFS(CN_일별!$D$4:$D$1372,CN_일별!$A$4:$A$1372,">="&$A7,CN_일별!$A$4:$A$1372,"<="&$B7),"") -> 0.036314522 | N7: =IF(OR(L7="",K7=""),"",(L7-K7)*10000) -> 49.553043 | O7: =LOOKUP($B7,정책금리_결정!$G$4:$G$9,정책금리_결정!$H$4:$H$9) -> 0.04 | P7: =IFERROR(AVERAGEIFS(VN_국채일별!$D$4:$D$1436,VN_국채일별!$A$4:$A$1436,">="&$A7,VN_국채일별!$A$4:$A$1436,"<="&$B7),"") -> 0.0062995652 | Q7: =IFERROR(SUMIFS(VN_은행채발행!$T$4:$T$712,VN_은행채발행!$C$4:$C$712,$A7)/SUMIFS(VN_은행채발행!$I$4:$I$712,VN_은행채발행!$C$4:$C$712,$A7,VN_은행채발행!$S$4:$S$712,1),"") | R7: =COUNTIFS(VN_은행채발행!$C$4:$C$712,$A7,VN_은행채발행!$S$4:$S$712,1) -> 0 | S7: =IFERROR(SUMIFS(VN_은행채발행!$U$4:$U$712,VN_은행채발행!$C$4:$C$712,$A7)/SUMIFS(VN_은행채발행!$Y$4:$Y$712,VN_은행채발행!$C$4:$C$712,$A7),"") | T7: =IFERROR(SUMIFS(VN_은행채발행!$W$4:$W$712,VN_은행채발행!$C$4:$C$712,$A7)/SUMIFS(VN_은행채발행!$I$4:$I$712,VN_은행채발행!$C$4:$C$712,$A7,VN_은행채발행!$V$4:$V$712,1),"") | U7: =IFERROR(SUMIFS(VN_은행채발행!$X$4:$X$712,VN_은행채발행!$C$4:$C$712,$A7)/SUMIFS(VN_은행채발행!$Z$4:$Z$712,VN_은행채발행!$C$4:$C$712,$A7),"") | V7: =LOOKUP($B7,정책금리_결정!$J$4:$J$49,정책금리_결정!$K$4:$K$49) -> 0.09 | W7: =IFERROR(AVERAGEIFS(KZ_일별!$C$4:$C$1352,KZ_일별!$A$4:$A$1352,">="&$A7,KZ_일별!$A$4:$A$1352,"<="&$B7),"") | X7: =IFERROR(AVERAGEIFS(KZ_일별!$E$4:$E$1352,KZ_일별!$A$4:$A$1352,">="&$A7,KZ_일별!$A$4:$A$1352,"<="&$B7),"") | Y7: =IFERROR(AVERAGEIFS(KZ_일별!$F$4:$F$1352,KZ_일별!$A$4:$A$1352,">="&$A7,KZ_일별!$A$4:$A$1352,"<="&$B7),"") -> 0.10643684 | Z7: =IFERROR(AVERAGEIFS(KZ_일별!$G$4:$G$1352,KZ_일별!$A$4:$A$1352,">="&$A7,KZ_일별!$A$4:$A$1352,"<="&$B7),"") | AA7: =IF(OR(Y7="",W7=""),"",(Y7-W7)*10000) | AB7: =IFERROR(AVERAGEIFS(KZ_일별!$H$4:$H$1352,KZ_일별!$A$4:$A$1352,">="&$A7,KZ_일별!$A$4:$A$1352,"<="&$B7),"") -> 0.091742105
A8: 44287 | B8: =EOMONTH(A8,0) -> 44316 | C8: =YEAR(A8)&"Q"&ROUNDUP(MONTH(A8)/3,0) -> 2021Q2 | D8: =YEAR(A8) -> 2021 | E8: =LOOKUP($B8,정책금리_결정!$A$4:$A$70,정책금리_결정!$B$4:$B$70) -> -0.001 | F8: =IFERROR(AVERAGEIFS(JP_국채일별!$C$4:$C$1345,JP_국채일별!$A$4:$A$1345,">="&$A8,JP_국채일별!$A$4:$A$1345,"<="&$B8),"") -> -0.001362381 | G8: =IFERROR(AVERAGEIFS(JP_등급별회사채!$D$4:$D$158,JP_등급별회사채!$A$4:$A$158,">="&$A8,JP_등급별회사채!$A$4:$A$158,"<="&$B8),"") -> 0.0012475 | H8: =IFERROR(AVERAGEIFS(JP_등급별회사채!$B$4:$B$158,JP_등급별회사채!$A$4:$A$158,">="&$A8,JP_등급별회사채!$A$4:$A$158,"<="&$B8),"") -> 0.0008825 | I8: =IF(OR(G8="",F8=""),"",(G8-F8)*10000) -> 26.09881 | J8: =LOOKUP($B8,정책금리_결정!$D$4:$D$70,정책금리_결정!$E$4:$E$70) -> 0.0385 | K8: =IFERROR(AVERAGEIFS(CN_일별!$B$4:$B$1372,CN_일별!$A$4:$A$1372,">="&$A8,CN_일별!$A$4:$A$1372,"<="&$B8),"") -> 0.028149818 | L8: =IFERROR(AVERAGEIFS(CN_일별!$C$4:$C$1372,CN_일별!$A$4:$A$1372,">="&$A8,CN_일별!$A$4:$A$1372,"<="&$B8),"") -> 0.033620636 | M8: =IFERROR(AVERAGEIFS(CN_일별!$D$4:$D$1372,CN_일별!$A$4:$A$1372,">="&$A8,CN_일별!$A$4:$A$1372,"<="&$B8),"") -> 0.035172318 | N8: =IF(OR(L8="",K8=""),"",(L8-K8)*10000) -> 54.708182 | O8: =LOOKUP($B8,정책금리_결정!$G$4:$G$9,정책금리_결정!$H$4:$H$9) -> 0.04 | P8: =IFERROR(AVERAGEIFS(VN_국채일별!$D$4:$D$1436,VN_국채일별!$A$4:$A$1436,">="&$A8,VN_국채일별!$A$4:$A$1436,"<="&$B8),"") -> 0.0062495455 | Q8: =IFERROR(SUMIFS(VN_은행채발행!$T$4:$T$712,VN_은행채발행!$C$4:$C$712,$A8)/SUMIFS(VN_은행채발행!$I$4:$I$712,VN_은행채발행!$C$4:$C$712,$A8,VN_은행채발행!$S$4:$S$712,1),"") | R8: =COUNTIFS(VN_은행채발행!$C$4:$C$712,$A8,VN_은행채발행!$S$4:$S$712,1) -> 0 | S8: =IFERROR(SUMIFS(VN_은행채발행!$U$4:$U$712,VN_은행채발행!$C$4:$C$712,$A8)/SUMIFS(VN_은행채발행!$Y$4:$Y$712,VN_은행채발행!$C$4:$C$712,$A8),"") | T8: =IFERROR(SUMIFS(VN_은행채발행!$W$4:$W$712,VN_은행채발행!$C$4:$C$712,$A8)/SUMIFS(VN_은행채발행!$I$4:$I$712,VN_은행채발행!$C$4:$C$712,$A8,VN_은행채발행!$V$4:$V$712,1),"") | U8: =IFERROR(SUMIFS(VN_은행채발행!$X$4:$X$712,VN_은행채발행!$C$4:$C$712,$A8)/SUMIFS(VN_은행채발행!$Z$4:$Z$712,VN_은행채발행!$C$4:$C$712,$A8),"") | V8: =LOOKUP($B8,정책금리_결정!$J$4:$J$49,정책금리_결정!$K$4:$K$49) -> 0.09 | W8: =IFERROR(AVERAGEIFS(KZ_일별!$C$4:$C$1352,KZ_일별!$A$4:$A$1352,">="&$A8,KZ_일별!$A$4:$A$1352,"<="&$B8),"") | X8: =IFERROR(AVERAGEIFS(KZ_일별!$E$4:$E$1352,KZ_일별!$A$4:$A$1352,">="&$A8,KZ_일별!$A$4:$A$1352,"<="&$B8),"") | Y8: =IFERROR(AVERAGEIFS(KZ_일별!$F$4:$F$1352,KZ_일별!$A$4:$A$1352,">="&$A8,KZ_일별!$A$4:$A$1352,"<="&$B8),"") -> 0.10620909 | Z8: =IFERROR(AVERAGEIFS(KZ_일별!$G$4:$G$1352,KZ_일별!$A$4:$A$1352,">="&$A8,KZ_일별!$A$4:$A$1352,"<="&$B8),"") | AA8: =IF(OR(Y8="",W8=""),"",(Y8-W8)*10000) | AB8: =IFERROR(AVERAGEIFS(KZ_일별!$H$4:$H$1352,KZ_일별!$A$4:$A$1352,">="&$A8,KZ_일별!$A$4:$A$1352,"<="&$B8),"") -> 0.086968182
A9: 44317 | B9: =EOMONTH(A9,0) -> 44347 | C9: =YEAR(A9)&"Q"&ROUNDUP(MONTH(A9)/3,0) -> 2021Q2 | D9: =YEAR(A9) -> 2021 | E9: =LOOKUP($B9,정책금리_결정!$A$4:$A$70,정책금리_결정!$B$4:$B$70) -> -0.001 | F9: =IFERROR(AVERAGEIFS(JP_국채일별!$C$4:$C$1345,JP_국채일별!$A$4:$A$1345,">="&$A9,JP_국채일별!$A$4:$A$1345,"<="&$B9),"") -> -0.001345 | G9: =IFERROR(AVERAGEIFS(JP_등급별회사채!$D$4:$D$158,JP_등급별회사채!$A$4:$A$158,">="&$A9,JP_등급별회사채!$A$4:$A$158,"<="&$B9),"") -> 0.001245 | H9: =IFERROR(AVERAGEIFS(JP_등급별회사채!$B$4:$B$158,JP_등급별회사채!$A$4:$A$158,">="&$A9,JP_등급별회사채!$A$4:$A$158,"<="&$B9),"") -> 0.0008125 | I9: =IF(OR(G9="",F9=""),"",(G9-F9)*10000) -> 25.9 | J9: =LOOKUP($B9,정책금리_결정!$D$4:$D$70,정책금리_결정!$E$4:$E$70) -> 0.0385 | K9: =IFERROR(AVERAGEIFS(CN_일별!$B$4:$B$1372,CN_일별!$A$4:$A$1372,">="&$A9,CN_일별!$A$4:$A$1372,"<="&$B9),"") -> 0.027420316 | L9: =IFERROR(AVERAGEIFS(CN_일별!$C$4:$C$1372,CN_일별!$A$4:$A$1372,">="&$A9,CN_일별!$A$4:$A$1372,"<="&$B9),"") -> 0.032263684 | M9: =IFERROR(AVERAGEIFS(CN_일별!$D$4:$D$1372,CN_일별!$A$4:$A$1372,">="&$A9,CN_일별!$A$4:$A$1372,"<="&$B9),"") -> 0.034229421 | N9: =IF(OR(L9="",K9=""),"",(L9-K9)*10000) -> 48.433684 | O9: =LOOKUP($B9,정책금리_결정!$G$4:$G$9,정책금리_결정!$H$4:$H$9) -> 0.04 | P9: =IFERROR(AVERAGEIFS(VN_국채일별!$D$4:$D$1436,VN_국채일별!$A$4:$A$1436,">="&$A9,VN_국채일별!$A$4:$A$1436,"<="&$B9),"") -> 0.007412381 | Q9: =IFERROR(SUMIFS(VN_은행채발행!$T$4:$T$712,VN_은행채발행!$C$4:$C$712,$A9)/SUMIFS(VN_은행채발행!$I$4:$I$712,VN_은행채발행!$C$4:$C$712,$A9,VN_은행채발행!$S$4:$S$712,1),"") | R9: =COUNTIFS(VN_은행채발행!$C$4:$C$712,$A9,VN_은행채발행!$S$4:$S$712,1) -> 0 | S9: =IFERROR(SUMIFS(VN_은행채발행!$U$4:$U$712,VN_은행채발행!$C$4:$C$712,$A9)/SUMIFS(VN_은행채발행!$Y$4:$Y$712,VN_은행채발행!$C$4:$C$712,$A9),"") | T9: =IFERROR(SUMIFS(VN_은행채발행!$W$4:$W$712,VN_은행채발행!$C$4:$C$712,$A9)/SUMIFS(VN_은행채발행!$I$4:$I$712,VN_은행채발행!$C$4:$C$712,$A9,VN_은행채발행!$V$4:$V$712,1),"") | U9: =IFERROR(SUMIFS(VN_은행채발행!$X$4:$X$712,VN_은행채발행!$C$4:$C$712,$A9)/SUMIFS(VN_은행채발행!$Z$4:$Z$712,VN_은행채발행!$C$4:$C$712,$A9),"") | V9: =LOOKUP($B9,정책금리_결정!$J$4:$J$49,정책금리_결정!$K$4:$K$49) -> 0.09 | W9: =IFERROR(AVERAGEIFS(KZ_일별!$C$4:$C$1352,KZ_일별!$A$4:$A$1352,">="&$A9,KZ_일별!$A$4:$A$1352,"<="&$B9),"") | X9: =IFERROR(AVERAGEIFS(KZ_일별!$E$4:$E$1352,KZ_일별!$A$4:$A$1352,">="&$A9,KZ_일별!$A$4:$A$1352,"<="&$B9),"") | Y9: =IFERROR(AVERAGEIFS(KZ_일별!$F$4:$F$1352,KZ_일별!$A$4:$A$1352,">="&$A9,KZ_일별!$A$4:$A$1352,"<="&$B9),"") -> 0.10557222 | Z9: =IFERROR(AVERAGEIFS(KZ_일별!$G$4:$G$1352,KZ_일별!$A$4:$A$1352,">="&$A9,KZ_일별!$A$4:$A$1352,"<="&$B9),"") | AA9: =IF(OR(Y9="",W9=""),"",(Y9-W9)*10000) | AB9: =IFERROR(AVERAGEIFS(KZ_일별!$H$4:$H$1352,KZ_일별!$A$4:$A$1352,">="&$A9,KZ_일별!$A$4:$A$1352,"<="&$B9),"") -> 0.081172222
A10: 44348 | B10: =EOMONTH(A10,0) -> 44377 | C10: =YEAR(A10)&"Q"&ROUNDUP(MONTH(A10)/3,0) -> 2021Q2 | D10: =YEAR(A10) -> 2021 | E10: =LOOKUP($B10,정책금리_결정!$A$4:$A$70,정책금리_결정!$B$4:$B$70) -> -0.001 | F10: =IFERROR(AVERAGEIFS(JP_국채일별!$C$4:$C$1345,JP_국채일별!$A$4:$A$1345,">="&$A10,JP_국채일별!$A$4:$A$1345,"<="&$B10),"") -> -0.0013027273 | G10: =IFERROR(AVERAGEIFS(JP_등급별회사채!$D$4:$D$158,JP_등급별회사채!$A$4:$A$158,">="&$A10,JP_등급별회사채!$A$4:$A$158,"<="&$B10),"") -> 0.0011775 | H10: =IFERROR(AVERAGEIFS(JP_등급별회사채!$B$4:$B$158,JP_등급별회사채!$A$4:$A$158,">="&$A10,JP_등급별회사채!$A$4:$A$158,"<="&$B10),"") -> 0.00071 | I10: =IF(OR(G10="",F10=""),"",(G10-F10)*10000) -> 24.802273 | J10: =LOOKUP($B10,정책금리_결정!$D$4:$D$70,정책금리_결정!$E$4:$E$70) -> 0.0385 | K10: =IFERROR(AVERAGEIFS(CN_일별!$B$4:$B$1372,CN_일별!$A$4:$A$1372,">="&$A10,CN_일별!$A$4:$A$1372,"<="&$B10),"") -> 0.028086667 | L10: =IFERROR(AVERAGEIFS(CN_일별!$C$4:$C$1372,CN_일별!$A$4:$A$1372,">="&$A10,CN_일별!$A$4:$A$1372,"<="&$B10),"") -> 0.032251238 | M10: =IFERROR(AVERAGEIFS(CN_일별!$D$4:$D$1372,CN_일별!$A$4:$A$1372,">="&$A10,CN_일별!$A$4:$A$1372,"<="&$B10),"") -> 0.034437857 | N10: =IF(OR(L10="",K10=""),"",(L10-K10)*10000) -> 41.645714 | O10: =LOOKUP($B10,정책금리_결정!$G$4:$G$9,정책금리_결정!$H$4:$H$9) -> 0.04 | P10: =IFERROR(AVERAGEIFS(VN_국채일별!$D$4:$D$1436,VN_국채일별!$A$4:$A$1436,">="&$A10,VN_국채일별!$A$4:$A$1436,"<="&$B10),"") -> 0.0081159091 | Q10: =IFERROR(SUMIFS(VN_은행채발행!$T$4:$T$712,VN_은행채발행!$C$4:$C$712,$A10)/SUMIFS(VN_은행채발행!$I$4:$I$712,VN_은행채발행!$C$4:$C$712,$A10,VN_은행채발행!$S$4:$S$712,1),"") | R10: =COUNTIFS(VN_은행채발행!$C$4:$C$712,$A10,VN_은행채발행!$S$4:$S$712,1) -> 0 | S10: =IFERROR(SUMIFS(VN_은행채발행!$U$4:$U$712,VN_은행채발행!$C$4:$C$712,$A10)/SUMIFS(VN_은행채발행!$Y$4:$Y$712,VN_은행채발행!$C$4:$C$712,$A10),"") | T10: =IFERROR(SUMIFS(VN_은행채발행!$W$4:$W$712,VN_은행채발행!$C$4:$C$712,$A10)/SUMIFS(VN_은행채발행!$I$4:$I$712,VN_은행채발행!$C$4:$C$712,$A10,VN_은행채발행!$V$4:$V$712,1),"") | U10: =IFERROR(SUMIFS(VN_은행채발행!$X$4:$X$712,VN_은행채발행!$C$4:$C$712,$A10)/SUMIFS(VN_은행채발행!$Z$4:$Z$712,VN_은행채발행!$C$4:$C$712,$A10),"") | V10: =LOOKUP($B10,정책금리_결정!$J$4:$J$49,정책금리_결정!$K$4:$K$49) -> 0.09 | W10: =IFERROR(AVERAGEIFS(KZ_일별!$C$4:$C$1352,KZ_일별!$A$4:$A$1352,">="&$A10,KZ_일별!$A$4:$A$1352,"<="&$B10),"") | X10: =IFERROR(AVERAGEIFS(KZ_일별!$E$4:$E$1352,KZ_일별!$A$4:$A$1352,">="&$A10,KZ_일별!$A$4:$A$1352,"<="&$B10),"") | Y10: =IFERROR(AVERAGEIFS(KZ_일별!$F$4:$F$1352,KZ_일별!$A$4:$A$1352,">="&$A10,KZ_일별!$A$4:$A$1352,"<="&$B10),"") -> 0.10521818 | Z10: =IFERROR(AVERAGEIFS(KZ_일별!$G$4:$G$1352,KZ_일별!$A$4:$A$1352,">="&$A10,KZ_일별!$A$4:$A$1352,"<="&$B10),"") | AA10: =IF(OR(Y10="",W10=""),"",(Y10-W10)*10000) | AB10: =IFERROR(AVERAGEIFS(KZ_일별!$H$4:$H$1352,KZ_일별!$A$4:$A$1352,">="&$A10,KZ_일별!$A$4:$A$1352,"<="&$B10),"") -> 0.083413636
A11: 44378 | B11: =EOMONTH(A11,0) -> 44408 | C11: =YEAR(A11)&"Q"&ROUNDUP(MONTH(A11)/3,0) -> 2021Q3 | D11: =YEAR(A11) -> 2021 | E11: =LOOKUP($B11,정책금리_결정!$A$4:$A$70,정책금리_결정!$B$4:$B$70) -> -0.001 | F11: =IFERROR(AVERAGEIFS(JP_국채일별!$C$4:$C$1345,JP_국채일별!$A$4:$A$1345,">="&$A11,JP_국채일별!$A$4:$A$1345,"<="&$B11),"") -> -0.0013825 | G11: =IFERROR(AVERAGEIFS(JP_등급별회사채!$D$4:$D$158,JP_등급별회사채!$A$4:$A$158,">="&$A11,JP_등급별회사채!$A$4:$A$158,"<="&$B11),"") -> 0.00106 | H11: =IFERROR(AVERAGEIFS(JP_등급별회사채!$B$4:$B$158,JP_등급별회사채!$A$4:$A$158,">="&$A11,JP_등급별회사채!$A$4:$A$158,"<="&$B11),"") -> 0.0006375 | I11: =IF(OR(G11="",F11=""),"",(G11-F11)*10000) -> 24.425 | J11: =LOOKUP($B11,정책금리_결정!$D$4:$D$70,정책금리_결정!$E$4:$E$70) -> 0.0385 | K11: =IFERROR(AVERAGEIFS(CN_일별!$B$4:$B$1372,CN_일별!$A$4:$A$1372,">="&$A11,CN_일별!$A$4:$A$1372,"<="&$B11),"") -> 0.026499909 | L11: =IFERROR(AVERAGEIFS(CN_일별!$C$4:$C$1372,CN_일별!$A$4:$A$1372,">="&$A11,CN_일별!$A$4:$A$1372,"<="&$B11),"") -> 0.030136364 | M11: =IFERROR(AVERAGEIFS(CN_일별!$D$4:$D$1372,CN_일별!$A$4:$A$1372,">="&$A11,CN_일별!$A$4:$A$1372,"<="&$B11),"") -> 0.032058818 | N11: =IF(OR(L11="",K11=""),"",(L11-K11)*10000) -> 36.364545 | O11: =LOOKUP($B11,정책금리_결정!$G$4:$G$9,정책금리_결정!$H$4:$H$9) -> 0.04 | P11: =IFERROR(AVERAGEIFS(VN_국채일별!$D$4:$D$1436,VN_국채일별!$A$4:$A$1436,">="&$A11,VN_국채일별!$A$4:$A$1436,"<="&$B11),"") -> 0.0078181818 | Q11: =IFERROR(SUMIFS(VN_은행채발행!$T$4:$T$712,VN_은행채발행!$C$4:$C$712,$A11)/SUMIFS(VN_은행채발행!$I$4:$I$712,VN_은행채발행!$C$4:$C$712,$A11,VN_은행채발행!$S$4:$S$712,1),"") | R11: =COUNTIFS(VN_은행채발행!$C$4:$C$712,$A11,VN_은행채발행!$S$4:$S$712,1) -> 0 | S11: =IFERROR(SUMIFS(VN_은행채발행!$U$4:$U$712,VN_은행채발행!$C$4:$C$712,$A11)/SUMIFS(VN_은행채발행!$Y$4:$Y$712,VN_은행채발행!$C$4:$C$712,$A11),"") | T11: =IFERROR(SUMIFS(VN_은행채발행!$W$4:$W$712,VN_은행채발행!$C$4:$C$712,$A11)/SUMIFS(VN_은행채발행!$I$4:$I$712,VN_은행채발행!$C$4:$C$712,$A11,VN_은행채발행!$V$4:$V$712,1),"") | U11: =IFERROR(SUMIFS(VN_은행채발행!$X$4:$X$712,VN_은행채발행!$C$4:$C$712,$A11)/SUMIFS(VN_은행채발행!$Z$4:$Z$712,VN_은행채발행!$C$4:$C$712,$A11),"") | V11: =LOOKUP($B11,정책금리_결정!$J$4:$J$49,정책금리_결정!$K$4:$K$49) -> 0.0925 | W11: =IFERROR(AVERAGEIFS(KZ_일별!$C$4:$C$1352,KZ_일별!$A$4:$A$1352,">="&$A11,KZ_일별!$A$4:$A$1352,"<="&$B11),"") | X11: =IFERROR(AVERAGEIFS(KZ_일별!$E$4:$E$1352,KZ_일별!$A$4:$A$1352,">="&$A11,KZ_일별!$A$4:$A$1352,"<="&$B11),"") | Y11: =IFERROR(AVERAGEIFS(KZ_일별!$F$4:$F$1352,KZ_일별!$A$4:$A$1352,">="&$A11,KZ_일별!$A$4:$A$1352,"<="&$B11),"") -> 0.10438 | Z11: =IFERROR(AVERAGEIFS(KZ_일별!$G$4:$G$1352,KZ_일별!$A$4:$A$1352,">="&$A11,KZ_일별!$A$4:$A$1352,"<="&$B11),"") | AA11: =IF(OR(Y11="",W11=""),"",(Y11-W11)*10000) | AB11: =IFERROR(AVERAGEIFS(KZ_일별!$H$4:$H$1352,KZ_일별!$A$4:$A$1352,">="&$A11,KZ_일별!$A$4:$A$1352,"<="&$B11),"") -> 0.08439
A12: 44409 | B12: =EOMONTH(A12,0) -> 44439 | C12: =YEAR(A12)&"Q"&ROUNDUP(MONTH(A12)/3,0) -> 2021Q3 | D12: =YEAR(A12) -> 2021 | E12: =LOOKUP($B12,정책금리_결정!$A$4:$A$70,정책금리_결정!$B$4:$B$70) -> -0.001 | F12: =IFERROR(AVERAGEIFS(JP_국채일별!$C$4:$C$1345,JP_국채일별!$A$4:$A$1345,">="&$A12,JP_국채일별!$A$4:$A$1345,"<="&$B12),"") -> -0.0013604762 | G12: =IFERROR(AVERAGEIFS(JP_등급별회사채!$D$4:$D$158,JP_등급별회사채!$A$4:$A$158,">="&$A12,JP_등급별회사채!$A$4:$A$158,"<="&$B12),"") -> 0.0010675 | H12: =IFERROR(AVERAGEIFS(JP_등급별회사채!$B$4:$B$158,JP_등급별회사채!$A$4:$A$158,">="&$A12,JP_등급별회사채!$A$4:$A$158,"<="&$B12),"") -> 0.000645 | I12: =IF(OR(G12="",F12=""),"",(G12-F12)*10000) -> 24.279762 | J12: =LOOKUP($B12,정책금리_결정!$D$4:$D$70,정책금리_결정!$E$4:$E$70) -> 0.0385 | K12: =IFERROR(AVERAGEIFS(CN_일별!$B$4:$B$1372,CN_일별!$A$4:$A$1372,">="&$A12,CN_일별!$A$4:$A$1372,"<="&$B12),"") -> 0.025689773 | L12: =IFERROR(AVERAGEIFS(CN_일별!$C$4:$C$1372,CN_일별!$A$4:$A$1372,">="&$A12,CN_일별!$A$4:$A$1372,"<="&$B12),"") -> 0.029205773 | M12: =IFERROR(AVERAGEIFS(CN_일별!$D$4:$D$1372,CN_일별!$A$4:$A$1372,">="&$A12,CN_일별!$A$4:$A$1372,"<="&$B12),"") -> 0.030648409 | N12: =IF(OR(L12="",K12=""),"",(L12-K12)*10000) -> 35.16 | O12: =LOOKUP($B12,정책금리_결정!$G$4:$G$9,정책금리_결정!$H$4:$H$9) -> 0.04 | P12: =IFERROR(AVERAGEIFS(VN_국채일별!$D$4:$D$1436,VN_국채일별!$A$4:$A$1436,">="&$A12,VN_국채일별!$A$4:$A$1436,"<="&$B12),"") -> 0.0069031818 | Q12: =IFERROR(SUMIFS(VN_은행채발행!$T$4:$T$712,VN_은행채발행!$C$4:$C$712,$A12)/SUMIFS(VN_은행채발행!$I$4:$I$712,VN_은행채발행!$C$4:$C$712,$A12,VN_은행채발행!$S$4:$S$712,1),"") -> 0.038026964 | R12: =COUNTIFS(VN_은행채발행!$C$4:$C$712,$A12,VN_은행채발행!$S$4:$S$712,1) -> 10 | S12: =IFERROR(SUMIFS(VN_은행채발행!$U$4:$U$712,VN_은행채발행!$C$4:$C$712,$A12)/SUMIFS(VN_은행채발행!$Y$4:$Y$712,VN_은행채발행!$C$4:$C$712,$A12),"") -> 314.39144 | T12: =IFERROR(SUMIFS(VN_은행채발행!$W$4:$W$712,VN_은행채발행!$C$4:$C$712,$A12)/SUMIFS(VN_은행채발행!$I$4:$I$712,VN_은행채발행!$C$4:$C$712,$A12,VN_은행채발행!$V$4:$V$712,1),"") | U12: =IFERROR(SUMIFS(VN_은행채발행!$X$4:$X$712,VN_은행채발행!$C$4:$C$712,$A12)/SUMIFS(VN_은행채발행!$Z$4:$Z$712,VN_은행채발행!$C$4:$C$712,$A12),"") | V12: =LOOKUP($B12,정책금리_결정!$J$4:$J$49,정책금리_결정!$K$4:$K$49) -> 0.0925 | W12: =IFERROR(AVERAGEIFS(KZ_일별!$C$4:$C$1352,KZ_일별!$A$4:$A$1352,">="&$A12,KZ_일별!$A$4:$A$1352,"<="&$B12),"") | X12: =IFERROR(AVERAGEIFS(KZ_일별!$E$4:$E$1352,KZ_일별!$A$4:$A$1352,">="&$A12,KZ_일별!$A$4:$A$1352,"<="&$B12),"") | Y12: =IFERROR(AVERAGEIFS(KZ_일별!$F$4:$F$1352,KZ_일별!$A$4:$A$1352,">="&$A12,KZ_일별!$A$4:$A$1352,"<="&$B12),"") -> 0.10290952 | Z12: =IFERROR(AVERAGEIFS(KZ_일별!$G$4:$G$1352,KZ_일별!$A$4:$A$1352,">="&$A12,KZ_일별!$A$4:$A$1352,"<="&$B12),"") | AA12: =IF(OR(Y12="",W12=""),"",(Y12-W12)*10000) | AB12: =IFERROR(AVERAGEIFS(KZ_일별!$H$4:$H$1352,KZ_일별!$A$4:$A$1352,">="&$A12,KZ_일별!$A$4:$A$1352,"<="&$B12),"") -> 0.09012381
A13: 44440 | B13: =EOMONTH(A13,0) -> 44469 | C13: =YEAR(A13)&"Q"&ROUNDUP(MONTH(A13)/3,0) -> 2021Q3 | D13: =YEAR(A13) -> 2021 | E13: =LOOKUP($B13,정책금리_결정!$A$4:$A$70,정책금리_결정!$B$4:$B$70) -> -0.001 | F13: =IFERROR(AVERAGEIFS(JP_국채일별!$C$4:$C$1345,JP_국채일별!$A$4:$A$1345,">="&$A13,JP_국채일별!$A$4:$A$1345,"<="&$B13),"") -> -0.001211 | G13: =IFERROR(AVERAGEIFS(JP_등급별회사채!$D$4:$D$158,JP_등급별회사채!$A$4:$A$158,">="&$A13,JP_등급별회사채!$A$4:$A$158,"<="&$B13),"") -> 0.001135 | H13: =IFERROR(AVERAGEIFS(JP_등급별회사채!$B$4:$B$158,JP_등급별회사채!$A$4:$A$158,">="&$A13,JP_등급별회사채!$A$4:$A$158,"<="&$B13),"") -> 0.0007575 | I13: =IF(OR(G13="",F13=""),"",(G13-F13)*10000) -> 23.46 | J13: =LOOKUP($B13,정책금리_결정!$D$4:$D$70,정책금리_결정!$E$4:$E$70) -> 0.0385 | K13: =IFERROR(AVERAGEIFS(CN_일별!$B$4:$B$1372,CN_일별!$A$4:$A$1372,">="&$A13,CN_일별!$A$4:$A$1372,"<="&$B13),"") -> 0.025567818 | L13: =IFERROR(AVERAGEIFS(CN_일별!$C$4:$C$1372,CN_일별!$A$4:$A$1372,">="&$A13,CN_일별!$A$4:$A$1372,"<="&$B13),"") -> 0.029640045 | M13: =IFERROR(AVERAGEIFS(CN_일별!$D$4:$D$1372,CN_일별!$A$4:$A$1372,">="&$A13,CN_일별!$A$4:$A$1372,"<="&$B13),"") -> 0.031198182 | N13: =IF(OR(L13="",K13=""),"",(L13-K13)*10000) -> 40.722273 | O13: =LOOKUP($B13,정책금리_결정!$G$4:$G$9,정책금리_결정!$H$4:$H$9) -> 0.04 | P13: =IFERROR(AVERAGEIFS(VN_국채일별!$D$4:$D$1436,VN_국채일별!$A$4:$A$1436,">="&$A13,VN_국채일별!$A$4:$A$1436,"<="&$B13),"") -> 0.0068759091 | Q13: =IFERROR(SUMIFS(VN_은행채발행!$T$4:$T$712,VN_은행채발행!$C$4:$C$712,$A13)/SUMIFS(VN_은행채발행!$I$4:$I$712,VN_은행채발행!$C$4:$C$712,$A13,VN_은행채발행!$S$4:$S$712,1),"") | R13: =COUNTIFS(VN_은행채발행!$C$4:$C$712,$A13,VN_은행채발행!$S$4:$S$712,1) -> 0 | S13: =IFERROR(SUMIFS(VN_은행채발행!$U$4:$U$712,VN_은행채발행!$C$4:$C$712,$A13)/SUMIFS(VN_은행채발행!$Y$4:$Y$712,VN_은행채발행!$C$4:$C$712,$A13),"") | T13: =IFERROR(SUMIFS(VN_은행채발행!$W$4:$W$712,VN_은행채발행!$C$4:$C$712,$A13)/SUMIFS(VN_은행채발행!$I$4:$I$712,VN_은행채발행!$C$4:$C$712,$A13,VN_은행채발행!$V$4:$V$712,1),"") | U13: =IFERROR(SUMIFS(VN_은행채발행!$X$4:$X$712,VN_은행채발행!$C$4:$C$712,$A13)/SUMIFS(VN_은행채발행!$Z$4:$Z$712,VN_은행채발행!$C$4:$C$712,$A13),"") | V13: =LOOKUP($B13,정책금리_결정!$J$4:$J$49,정책금리_결정!$K$4:$K$49) -> 0.095 | W13: =IFERROR(AVERAGEIFS(KZ_일별!$C$4:$C$1352,KZ_일별!$A$4:$A$1352,">="&$A13,KZ_일별!$A$4:$A$1352,"<="&$B13),"") | X13: =IFERROR(AVERAGEIFS(KZ_일별!$E$4:$E$1352,KZ_일별!$A$4:$A$1352,">="&$A13,KZ_일별!$A$4:$A$1352,"<="&$B13),"") | Y13: =IFERROR(AVERAGEIFS(KZ_일별!$F$4:$F$1352,KZ_일별!$A$4:$A$1352,">="&$A13,KZ_일별!$A$4:$A$1352,"<="&$B13),"") -> 0.10261364 | Z13: =IFERROR(AVERAGEIFS(KZ_일별!$G$4:$G$1352,KZ_일별!$A$4:$A$1352,">="&$A13,KZ_일별!$A$4:$A$1352,"<="&$B13),"") | AA13: =IF(OR(Y13="",W13=""),"",(Y13-W13)*10000) | AB13: =IFERROR(AVERAGEIFS(KZ_일별!$H$4:$H$1352,KZ_일별!$A$4:$A$1352,">="&$A13,KZ_일별!$A$4:$A$1352,"<="&$B13),"") -> 0.089195455
A14: 44470 | B14: =EOMONTH(A14,0) -> 44500 | C14: =YEAR(A14)&"Q"&ROUNDUP(MONTH(A14)/3,0) -> 2021Q4 | D14: =YEAR(A14) -> 2021 | E14: =LOOKUP($B14,정책금리_결정!$A$4:$A$70,정책금리_결정!$B$4:$B$70) -> -0.001 | F14: =IFERROR(AVERAGEIFS(JP_국채일별!$C$4:$C$1345,JP_국채일별!$A$4:$A$1345,">="&$A14,JP_국채일별!$A$4:$A$1345,"<="&$B14),"") -> -0.0011052381 | G14: =IFERROR(AVERAGEIFS(JP_등급별회사채!$D$4:$D$158,JP_등급별회사채!$A$4:$A$158,">="&$A14,JP_등급별회사채!$A$4:$A$158,"<="&$B14),"") -> 0.0012325 | H14: =IFERROR(AVERAGEIFS(JP_등급별회사채!$B$4:$B$158,JP_등급별회사채!$A$4:$A$158,">="&$A14,JP_등급별회사채!$A$4:$A$158,"<="&$B14),"") -> 0.0008975 | I14: =IF(OR(G14="",F14=""),"",(G14-F14)*10000) -> 23.377381 | J14: =LOOKUP($B14,정책금리_결정!$D$4:$D$70,정책금리_결정!$E$4:$E$70) -> 0.0385 | K14: =IFERROR(AVERAGEIFS(CN_일별!$B$4:$B$1372,CN_일별!$A$4:$A$1372,">="&$A14,CN_일별!$A$4:$A$1372,"<="&$B14),"") -> 0.026459941 | L14: =IFERROR(AVERAGEIFS(CN_일별!$C$4:$C$1372,CN_일별!$A$4:$A$1372,">="&$A14,CN_일별!$A$4:$A$1372,"<="&$B14),"") -> 0.030599588 | M14: =IFERROR(AVERAGEIFS(CN_일별!$D$4:$D$1372,CN_일별!$A$4:$A$1372,">="&$A14,CN_일별!$A$4:$A$1372,"<="&$B14),"") -> 0.032643059 | N14: =IF(OR(L14="",K14=""),"",(L14-K14)*10000) -> 41.396471 | O14: =LOOKUP($B14,정책금리_결정!$G$4:$G$9,정책금리_결정!$H$4:$H$9) -> 0.04 | P14: =IFERROR(AVERAGEIFS(VN_국채일별!$D$4:$D$1436,VN_국채일별!$A$4:$A$1436,">="&$A14,VN_국채일별!$A$4:$A$1436,"<="&$B14),"") -> 0.0074038095 | Q14: =IFERROR(SUMIFS(VN_은행채발행!$T$4:$T$712,VN_은행채발행!$C$4:$C$712,$A14)/SUMIFS(VN_은행채발행!$I$4:$I$712,VN_은행채발행!$C$4:$C$712,$A14,VN_은행채발행!$S$4:$S$712,1),"") | R14: =COUNTIFS(VN_은행채발행!$C$4:$C$712,$A14,VN_은행채발행!$S$4:$S$712,1) -> 0 | S14: =IFERROR(SUMIFS(VN_은행채발행!$U$4:$U$712,VN_은행채발행!$C$4:$C$712,$A14)/SUMIFS(VN_은행채발행!$Y$4:$Y$712,VN_은행채발행!$C$4:$C$712,$A14),"") | T14: =IFERROR(SUMIFS(VN_은행채발행!$W$4:$W$712,VN_은행채발행!$C$4:$C$712,$A14)/SUMIFS(VN_은행채발행!$I$4:$I$712,VN_은행채발행!$C$4:$C$712,$A14,VN_은행채발행!$V$4:$V$712,1),"") | U14: =IFERROR(SUMIFS(VN_은행채발행!$X$4:$X$712,VN_은행채발행!$C$4:$C$712,$A14)/SUMIFS(VN_은행채발행!$Z$4:$Z$712,VN_은행채발행!$C$4:$C$712,$A14),"") | V14: =LOOKUP($B14,정책금리_결정!$J$4:$J$49,정책금리_결정!$K$4:$K$49) -> 0.0975 | W14: =IFERROR(AVERAGEIFS(KZ_일별!$C$4:$C$1352,KZ_일별!$A$4:$A$1352,">="&$A14,KZ_일별!$A$4:$A$1352,"<="&$B14),"") | X14: =IFERROR(AVERAGEIFS(KZ_일별!$E$4:$E$1352,KZ_일별!$A$4:$A$1352,">="&$A14,KZ_일별!$A$4:$A$1352,"<="&$B14),"") | Y14: =IFERROR(AVERAGEIFS(KZ_일별!$F$4:$F$1352,KZ_일별!$A$4:$A$1352,">="&$A14,KZ_일별!$A$4:$A$1352,"<="&$B14),"") -> 0.10291905 | Z14: =IFERROR(AVERAGEIFS(KZ_일별!$G$4:$G$1352,KZ_일별!$A$4:$A$1352,">="&$A14,KZ_일별!$A$4:$A$1352,"<="&$B14),"") | AA14: =IF(OR(Y14="",W14=""),"",(Y14-W14)*10000) | AB14: =IFERROR(AVERAGEIFS(KZ_일별!$H$4:$H$1352,KZ_일별!$A$4:$A$1352,">="&$A14,KZ_일별!$A$4:$A$1352,"<="&$B14),"") -> 0.090338095
A15: 44501 | B15: =EOMONTH(A15,0) -> 44530 | C15: =YEAR(A15)&"Q"&ROUNDUP(MONTH(A15)/3,0) -> 2021Q4 | D15: =YEAR(A15) -> 2021 | E15: =LOOKUP($B15,정책금리_결정!$A$4:$A$70,정책금리_결정!$B$4:$B$70) -> -0.001 | F15: =IFERROR(AVERAGEIFS(JP_국채일별!$C$4:$C$1345,JP_국채일별!$A$4:$A$1345,">="&$A15,JP_국채일별!$A$4:$A$1345,"<="&$B15),"") -> -0.001166 | G15: =IFERROR(AVERAGEIFS(JP_등급별회사채!$D$4:$D$158,JP_등급별회사채!$A$4:$A$158,">="&$A15,JP_등급별회사채!$A$4:$A$158,"<="&$B15),"") -> 0.00117 | H15: =IFERROR(AVERAGEIFS(JP_등급별회사채!$B$4:$B$158,JP_등급별회사채!$A$4:$A$158,">="&$A15,JP_등급별회사채!$A$4:$A$158,"<="&$B15),"") -> 0.000875 | I15: =IF(OR(G15="",F15=""),"",(G15-F15)*10000) -> 23.36 | J15: =LOOKUP($B15,정책금리_결정!$D$4:$D$70,정책금리_결정!$E$4:$E$70) -> 0.0385 | K15: =IFERROR(AVERAGEIFS(CN_일별!$B$4:$B$1372,CN_일별!$A$4:$A$1372,">="&$A15,CN_일별!$A$4:$A$1372,"<="&$B15),"") -> 0.026132318 | L15: =IFERROR(AVERAGEIFS(CN_일별!$C$4:$C$1372,CN_일별!$A$4:$A$1372,">="&$A15,CN_일별!$A$4:$A$1372,"<="&$B15),"") -> 0.029307136 | M15: =IFERROR(AVERAGEIFS(CN_일별!$D$4:$D$1372,CN_일별!$A$4:$A$1372,">="&$A15,CN_일별!$A$4:$A$1372,"<="&$B15),"") -> 0.031191364 | N15: =IF(OR(L15="",K15=""),"",(L15-K15)*10000) -> 31.748182 | O15: =LOOKUP($B15,정책금리_결정!$G$4:$G$9,정책금리_결정!$H$4:$H$9) -> 0.04 | P15: =IFERROR(AVERAGEIFS(VN_국채일별!$D$4:$D$1436,VN_국채일별!$A$4:$A$1436,">="&$A15,VN_국채일별!$A$4:$A$1436,"<="&$B15),"") -> 0.0067513636 | Q15: =IFERROR(SUMIFS(VN_은행채발행!$T$4:$T$712,VN_은행채발행!$C$4:$C$712,$A15)/SUMIFS(VN_은행채발행!$I$4:$I$712,VN_은행채발행!$C$4:$C$712,$A15,VN_은행채발행!$S$4:$S$712,1),"") -> 0.036253968 | R15: =COUNTIFS(VN_은행채발행!$C$4:$C$712,$A15,VN_은행채발행!$S$4:$S$712,1) -> 5 | S15: =IFERROR(SUMIFS(VN_은행채발행!$U$4:$U$712,VN_은행채발행!$C$4:$C$712,$A15)/SUMIFS(VN_은행채발행!$Y$4:$Y$712,VN_은행채발행!$C$4:$C$712,$A15),"") -> 294.07619 | T15: =IFERROR(SUMIFS(VN_은행채발행!$W$4:$W$712,VN_은행채발행!$C$4:$C$712,$A15)/SUMIFS(VN_은행채발행!$I$4:$I$712,VN_은행채발행!$C$4:$C$712,$A15,VN_은행채발행!$V$4:$V$712,1),"") | U15: =IFERROR(SUMIFS(VN_은행채발행!$X$4:$X$712,VN_은행채발행!$C$4:$C$712,$A15)/SUMIFS(VN_은행채발행!$Z$4:$Z$712,VN_은행채발행!$C$4:$C$712,$A15),"") | V15: =LOOKUP($B15,정책금리_결정!$J$4:$J$49,정책금리_결정!$K$4:$K$49) -> 0.0975 | W15: =IFERROR(AVERAGEIFS(KZ_일별!$C$4:$C$1352,KZ_일별!$A$4:$A$1352,">="&$A15,KZ_일별!$A$4:$A$1352,"<="&$B15),"") | X15: =IFERROR(AVERAGEIFS(KZ_일별!$E$4:$E$1352,KZ_일별!$A$4:$A$1352,">="&$A15,KZ_일별!$A$4:$A$1352,"<="&$B15),"") | Y15: =IFERROR(AVERAGEIFS(KZ_일별!$F$4:$F$1352,KZ_일별!$A$4:$A$1352,">="&$A15,KZ_일별!$A$4:$A$1352,"<="&$B15),"") -> 0.10240909 | Z15: =IFERROR(AVERAGEIFS(KZ_일별!$G$4:$G$1352,KZ_일별!$A$4:$A$1352,">="&$A15,KZ_일별!$A$4:$A$1352,"<="&$B15),"") | AA15: =IF(OR(Y15="",W15=""),"",(Y15-W15)*10000) | AB15: =IFERROR(AVERAGEIFS(KZ_일별!$H$4:$H$1352,KZ_일별!$A$4:$A$1352,">="&$A15,KZ_일별!$A$4:$A$1352,"<="&$B15),"") -> 0.093586364
A16: 44531 | B16: =EOMONTH(A16,0) -> 44561 | C16: =YEAR(A16)&"Q"&ROUNDUP(MONTH(A16)/3,0) -> 2021Q4 | D16: =YEAR(A16) -> 2021 | E16: =LOOKUP($B16,정책금리_결정!$A$4:$A$70,정책금리_결정!$B$4:$B$70) -> -0.001 | F16: =IFERROR(AVERAGEIFS(JP_국채일별!$C$4:$C$1345,JP_국채일별!$A$4:$A$1345,">="&$A16,JP_국채일별!$A$4:$A$1345,"<="&$B16),"") -> -0.0011163636 | G16: =IFERROR(AVERAGEIFS(JP_등급별회사채!$D$4:$D$158,JP_등급별회사채!$A$4:$A$158,">="&$A16,JP_등급별회사채!$A$4:$A$158,"<="&$B16),"") -> 0.0011025 | H16: =IFERROR(AVERAGEIFS(JP_등급별회사채!$B$4:$B$158,JP_등급별회사채!$A$4:$A$158,">="&$A16,JP_등급별회사채!$A$4:$A$158,"<="&$B16),"") -> 0.00086 | I16: =IF(OR(G16="",F16=""),"",(G16-F16)*10000) -> 22.188636 | J16: =LOOKUP($B16,정책금리_결정!$D$4:$D$70,정책금리_결정!$E$4:$E$70) -> 0.038 | K16: =IFERROR(AVERAGEIFS(CN_일별!$B$4:$B$1372,CN_일별!$A$4:$A$1372,">="&$A16,CN_일별!$A$4:$A$1372,"<="&$B16),"") -> 0.025690391 | L16: =IFERROR(AVERAGEIFS(CN_일별!$C$4:$C$1372,CN_일별!$A$4:$A$1372,">="&$A16,CN_일별!$A$4:$A$1372,"<="&$B16),"") -> 0.028906565 | M16: =IFERROR(AVERAGEIFS(CN_일별!$D$4:$D$1372,CN_일별!$A$4:$A$1372,">="&$A16,CN_일별!$A$4:$A$1372,"<="&$B16),"") -> 0.030022043 | N16: =IF(OR(L16="",K16=""),"",(L16-K16)*10000) -> 32.161739 | O16: =LOOKUP($B16,정책금리_결정!$G$4:$G$9,정책금리_결정!$H$4:$H$9) -> 0.04 | P16: =IFERROR(AVERAGEIFS(VN_국채일별!$D$4:$D$1436,VN_국채일별!$A$4:$A$1436,">="&$A16,VN_국채일별!$A$4:$A$1436,"<="&$B16),"") -> 0.0069621739 | Q16: =IFERROR(SUMIFS(VN_은행채발행!$T$4:$T$712,VN_은행채발행!$C$4:$C$712,$A16)/SUMIFS(VN_은행채발행!$I$4:$I$712,VN_은행채발행!$C$4:$C$712,$A16,VN_은행채발행!$S$4:$S$712,1),"") -> 0.032210191 | R16: =COUNTIFS(VN_은행채발행!$C$4:$C$712,$A16,VN_은행채발행!$S$4:$S$712,1) -> 17 | S16: =IFERROR(SUMIFS(VN_은행채발행!$U$4:$U$712,VN_은행채발행!$C$4:$C$712,$A16)/SUMIFS(VN_은행채발행!$Y$4:$Y$712,VN_은행채발행!$C$4:$C$712,$A16),"") -> 256.19682 | T16: =IFERROR(SUMIFS(VN_은행채발행!$W$4:$W$712,VN_은행채발행!$C$4:$C$712,$A16)/SUMIFS(VN_은행채발행!$I$4:$I$712,VN_은행채발행!$C$4:$C$712,$A16,VN_은행채발행!$V$4:$V$712,1),"") | U16: =IFERROR(SUMIFS(VN_은행채발행!$X$4:$X$712,VN_은행채발행!$C$4:$C$712,$A16)/SUMIFS(VN_은행채발행!$Z$4:$Z$712,VN_은행채발행!$C$4:$C$712,$A16),"") | V16: =LOOKUP($B16,정책금리_결정!$J$4:$J$49,정책금리_결정!$K$4:$K$49) -> 0.0975 | W16: =IFERROR(AVERAGEIFS(KZ_일별!$C$4:$C$1352,KZ_일별!$A$4:$A$1352,">="&$A16,KZ_일별!$A$4:$A$1352,"<="&$B16),"") | X16: =IFERROR(AVERAGEIFS(KZ_일별!$E$4:$E$1352,KZ_일별!$A$4:$A$1352,">="&$A16,KZ_일별!$A$4:$A$1352,"<="&$B16),"") | Y16: =IFERROR(AVERAGEIFS(KZ_일별!$F$4:$F$1352,KZ_일별!$A$4:$A$1352,">="&$A16,KZ_일별!$A$4:$A$1352,"<="&$B16),"") -> 0.10511 | Z16: =IFERROR(AVERAGEIFS(KZ_일별!$G$4:$G$1352,KZ_일별!$A$4:$A$1352,">="&$A16,KZ_일별!$A$4:$A$1352,"<="&$B16),"") | AA16: =IF(OR(Y16="",W16=""),"",(Y16-W16)*10000) | AB16: =IFERROR(AVERAGEIFS(KZ_일별!$H$4:$H$1352,KZ_일별!$A$4:$A$1352,">="&$A16,KZ_일별!$A$4:$A$1352,"<="&$B16),"") -> 0.104985
... A70: 46174 | B70: =EOMONTH(A70,0) -> 46203 | C70: =YEAR(A70)&"Q"&ROUNDUP(MONTH(A70)/3,0) -> 2026Q2 | D70: =YEAR(A70) -> 2026 | E70: =LOOKUP($B70,정책금리_결정!$A$4:$A$70,정책금리_결정!$B$4:$B$70) -> 0.01 | F70: =IFERROR(AVERAGEIFS(JP_국채일별!$C$4:$C$1345,JP_국채일별!$A$4:$A$1345,">="&$A70,JP_국채일별!$A$4:$A$1345,"<="&$B70),"") -> 0.015645 | G70: =IFERROR(AVERAGEIFS(JP_등급별회사채!$D$4:$D$158,JP_등급별회사채!$A$4:$A$158,">="&$A70,JP_등급별회사채!$A$4:$A$158,"<="&$B70),"") -> 0.01972 | H70: =IFERROR(AVERAGEIFS(JP_등급별회사채!$B$4:$B$158,JP_등급별회사채!$A$4:$A$158,">="&$A70,JP_등급별회사채!$A$4:$A$158,"<="&$B70),"") -> 0.01902 | I70: =IF(OR(G70="",F70=""),"",(G70-F70)*10000) -> 40.75 | J70: =LOOKUP($B70,정책금리_결정!$D$4:$D$70,정책금리_결정!$E$4:$E$70) -> 0.03 | K70: =IFERROR(AVERAGEIFS(CN_일별!$B$4:$B$1372,CN_일별!$A$4:$A$1372,">="&$A70,CN_일별!$A$4:$A$1372,"<="&$B70),"") -> 0.012938429 | L70: =IFERROR(AVERAGEIFS(CN_일별!$C$4:$C$1372,CN_일별!$A$4:$A$1372,">="&$A70,CN_일별!$A$4:$A$1372,"<="&$B70),"") -> 0.015166048 | M70: =IFERROR(AVERAGEIFS(CN_일별!$D$4:$D$1372,CN_일별!$A$4:$A$1372,">="&$A70,CN_일별!$A$4:$A$1372,"<="&$B70),"") -> 0.01647981 | N70: =IF(OR(L70="",K70=""),"",(L70-K70)*10000) -> 22.27619 | O70: =LOOKUP($B70,정책금리_결정!$G$4:$G$9,정책금리_결정!$H$4:$H$9) -> 0.045 | P70: =IFERROR(AVERAGEIFS(VN_국채일별!$D$4:$D$1436,VN_국채일별!$A$4:$A$1436,">="&$A70,VN_국채일별!$A$4:$A$1436,"<="&$B70),"") -> 0.037111818 | Q70: =IFERROR(SUMIFS(VN_은행채발행!$T$4:$T$712,VN_은행채발행!$C$4:$C$712,$A70)/SUMIFS(VN_은행채발행!$I$4:$I$712,VN_은행채발행!$C$4:$C$712,$A70,VN_은행채발행!$S$4:$S$712,1),"") -> 0.084420279 | R70: =COUNTIFS(VN_은행채발행!$C$4:$C$712,$A70,VN_은행채발행!$S$4:$S$712,1) -> 10 | S70: =IFERROR(SUMIFS(VN_은행채발행!$U$4:$U$712,VN_은행채발행!$C$4:$C$712,$A70)/SUMIFS(VN_은행채발행!$Y$4:$Y$712,VN_은행채발행!$C$4:$C$712,$A70),"") -> 477.39287 | T70: =IFERROR(SUMIFS(VN_은행채발행!$W$4:$W$712,VN_은행채발행!$C$4:$C$712,$A70)/SUMIFS(VN_은행채발행!$I$4:$I$712,VN_은행채발행!$C$4:$C$712,$A70,VN_은행채발행!$V$4:$V$712,1),"") | U70: =IFERROR(SUMIFS(VN_은행채발행!$X$4:$X$712,VN_은행채발행!$C$4:$C$712,$A70)/SUMIFS(VN_은행채발행!$Z$4:$Z$712,VN_은행채발행!$C$4:$C$712,$A70),"") | V70: =LOOKUP($B70,정책금리_결정!$J$4:$J$49,정책금리_결정!$K$4:$K$49) -> 0.17 | W70: =IFERROR(AVERAGEIFS(KZ_일별!$C$4:$C$1352,KZ_일별!$A$4:$A$1352,">="&$A70,KZ_일별!$A$4:$A$1352,"<="&$B70),"") -> 0.16384091 | X70: =IFERROR(AVERAGEIFS(KZ_일별!$E$4:$E$1352,KZ_일별!$A$4:$A$1352,">="&$A70,KZ_일별!$A$4:$A$1352,"<="&$B70),"") -> 0.16536773 | Y70: =IFERROR(AVERAGEIFS(KZ_일별!$F$4:$F$1352,KZ_일별!$A$4:$A$1352,">="&$A70,KZ_일별!$A$4:$A$1352,"<="&$B70),"") -> 0.16598636 | Z70: =IFERROR(AVERAGEIFS(KZ_일별!$G$4:$G$1352,KZ_일별!$A$4:$A$1352,">="&$A70,KZ_일별!$A$4:$A$1352,"<="&$B70),"") -> 0.15265 | AA70: =IF(OR(Y70="",W70=""),"",(Y70-W70)*10000) -> 21.454545 | AB70: =IFERROR(AVERAGEIFS(KZ_일별!$H$4:$H$1352,KZ_일별!$A$4:$A$1352,">="&$A70,KZ_일별!$A$4:$A$1352,"<="&$B70),"") -> 0.17049091
A72: 노란 행 = 측정 기준월(2025.12). 일본 회사채 등급별 수익률은 월 1~4영업일 샘플 평균(2025.12는 전 영업일). 카자흐 국채지수는 2022.03부터, KASE_KZ3_Y는 2026.04부터 제공. 베트남 은행채는 발행이 없는 달 공란.

Sheet 분기·연도별
A1: 분기·연도별 평균 (월별 시트의 월평균을 평균, 정책금리는 기말값, 베트남 은행채는 기간 발행액 가중)
A2: 분기 = 해당 분기 3개월 월평균의 평균. 연도 행의 2026은 상반기(1~6월).
C3: 일본 (JPY) | H3: 중국 (CNY) | M3: 베트남 (VND) | T3: 카자흐스탄 (KZT)
A4: 기간 | B4: 기말일 | C4: 정책금리 (월말) | D4: JGB 3Y | E4: 회사채 R&I AA 잔존3Y | F4: 회사채 R&I AAA 잔존3Y(참고) | G4: 스프레드 AA−JGB | H4: LPR 1Y (월말) | I4: 국채 3Y | J4: 상업은행채 AAA 3Y | K4: MTN AAA 3Y (참고) | L4: 스프레드 은행AAA−국채 | M4: 재할인율 (월말) | N4: VGB 3Y | O4: 은행채 발행금리 선순위고정2~4Y (가중) | P4: 발행 건수 | Q4: 스프레드 (동일만기 국채대비, 가중) | R4: Big4 선순위 고정 발행금리 (가중) | S4: Big4 스프레드 | T4: 기준금리 (월말) | U4: 국채지수 1~5Y | V4: 국채 3Y (WGB,참고) | W4: 회사채지수 KASE_BMY | X4: BBB-이상 회사채 KASE_KZ3_Y | Y4: 스프레드 BMY−국채1~5Y | Z4: TONIA (월평균)
A5: 2021Q1 | B5: =EOMONTH(DATE(2021,3,1),0) -> 44286 | C5: =LOOKUP($B5,정책금리_결정!$A$4:$A$70,정책금리_결정!$B$4:$B$70) -> -0.001 | D5: =IFERROR(AVERAGEIFS(월별!$F$5:$F$70,월별!$C$5:$C$70,"2021Q1"),"") -> -0.001260614 | E5: =IFERROR(AVERAGEIFS(월별!$G$5:$G$70,월별!$C$5:$C$70,"2021Q1"),"") -> 0.0013713636 | F5: =IFERROR(AVERAGEIFS(월별!$H$5:$H$70,월별!$C$5:$C$70,"2021Q1"),"") -> 0.001351197 | G5: =IFERROR(AVERAGEIFS(월별!$I$5:$I$70,월별!$C$5:$C$70,"2021Q1"),"") -> 26.319777 | H5: =LOOKUP($B5,정책금리_결정!$D$4:$D$70,정책금리_결정!$E$4:$E$70) -> 0.0385 | I5: =IFERROR(AVERAGEIFS(월별!$K$5:$K$70,월별!$C$5:$C$70,"2021Q1"),"") -> 0.028707279 | J5: =IFERROR(AVERAGEIFS(월별!$L$5:$L$70,월별!$C$5:$C$70,"2021Q1"),"") -> 0.034040749 | K5: =IFERROR(AVERAGEIFS(월별!$M$5:$M$70,월별!$C$5:$C$70,"2021Q1"),"") -> 0.036201584 | L5: =IFERROR(AVERAGEIFS(월별!$N$5:$N$70,월별!$C$5:$C$70,"2021Q1"),"") -> 53.334701 | M5: =LOOKUP($B5,정책금리_결정!$G$4:$G$9,정책금리_결정!$H$4:$H$9) -> 0.04 | N5: =IFERROR(AVERAGEIFS(월별!$P$5:$P$70,월별!$C$5:$C$70,"2021Q1"),"") -> 0.0063076725 | O5: =IFERROR(SUMIFS(VN_은행채발행!$T$4:$T$712,VN_은행채발행!$D$4:$D$712,"2021Q1")/SUMIFS(VN_은행채발행!$I$4:$I$712,VN_은행채발행!$D$4:$D$712,"2021Q1",VN_은행채발행!$S$4:$S$712,1),"") | P5: =SUMIFS(월별!$R$5:$R$70,월별!$C$5:$C$70,"2021Q1") -> 0 | Q5: =IFERROR(SUMIFS(VN_은행채발행!$U$4:$U$712,VN_은행채발행!$D$4:$D$712,"2021Q1")/SUMIFS(VN_은행채발행!$Y$4:$Y$712,VN_은행채발행!$D$4:$D$712,"2021Q1"),"") | R5: =IFERROR(SUMIFS(VN_은행채발행!$W$4:$W$712,VN_은행채발행!$D$4:$D$712,"2021Q1")/SUMIFS(VN_은행채발행!$I$4:$I$712,VN_은행채발행!$D$4:$D$712,"2021Q1",VN_은행채발행!$V$4:$V$712,1),"") | S5: =IFERROR(SUMIFS(VN_은행채발행!$X$4:$X$712,VN_은행채발행!$D$4:$D$712,"2021Q1")/SUMIFS(VN_은행채발행!$Z$4:$Z$712,VN_은행채발행!$D$4:$D$712,"2021Q1"),"") | T5: =LOOKUP($B5,정책금리_결정!$J$4:$J$49,정책금리_결정!$K$4:$K$49) -> 0.09 | U5: =IFERROR(AVERAGEIFS(월별!$W$5:$W$70,월별!$C$5:$C$70,"2021Q1"),"") | V5: =IFERROR(AVERAGEIFS(월별!$X$5:$X$70,월별!$C$5:$C$70,"2021Q1"),"") | W5: =IFERROR(AVERAGEIFS(월별!$Y$5:$Y$70,월별!$C$5:$C$70,"2021Q1"),"") -> 0.10708802 | X5: =IFERROR(AVERAGEIFS(월별!$Z$5:$Z$70,월별!$C$5:$C$70,"2021Q1"),"") | Y5: =IFERROR(AVERAGEIFS(월별!$AA$5:$AA$70,월별!$C$5:$C$70,"2021Q1"),"") | Z5: =IFERROR(AVERAGEIFS(월별!$AB$5:$AB$70,월별!$C$5:$C$70,"2021Q1"),"") -> 0.087017368
A6: 2021Q2 | B6: =EOMONTH(DATE(2021,6,1),0) -> 44377 | C6: =LOOKUP($B6,정책금리_결정!$A$4:$A$70,정책금리_결정!$B$4:$B$70) -> -0.001 | D6: =IFERROR(AVERAGEIFS(월별!$F$5:$F$70,월별!$C$5:$C$70,"2021Q2"),"") -> -0.0013367027 | E6: =IFERROR(AVERAGEIFS(월별!$G$5:$G$70,월별!$C$5:$C$70,"2021Q2"),"") -> 0.0012233333 | F6: =IFERROR(AVERAGEIFS(월별!$H$5:$H$70,월별!$C$5:$C$70,"2021Q2"),"") -> 0.00080166667 | G6: =IFERROR(AVERAGEIFS(월별!$I$5:$I$70,월별!$C$5:$C$70,"2021Q2"),"") -> 25.600361 | H6: =LOOKUP($B6,정책금리_결정!$D$4:$D$70,정책금리_결정!$E$4:$E$70) -> 0.0385 | I6: =IFERROR(AVERAGEIFS(월별!$K$5:$K$70,월별!$C$5:$C$70,"2021Q2"),"") -> 0.0278856 | J6: =IFERROR(AVERAGEIFS(월별!$L$5:$L$70,월별!$C$5:$C$70,"2021Q2"),"") -> 0.032711853 | K6: =IFERROR(AVERAGEIFS(월별!$M$5:$M$70,월별!$C$5:$C$70,"2021Q2"),"") -> 0.034613199 | L6: =IFERROR(AVERAGEIFS(월별!$N$5:$N$70,월별!$C$5:$C$70,"2021Q2"),"") -> 48.262527 | M6: =LOOKUP($B6,정책금리_결정!$G$4:$G$9,정책금리_결정!$H$4:$H$9) -> 0.04 | N6: =IFERROR(AVERAGEIFS(월별!$P$5:$P$70,월별!$C$5:$C$70,"2021Q2"),"") -> 0.0072592785 | O6: =IFERROR(SUMIFS(VN_은행채발행!$T$4:$T$712,VN_은행채발행!$D$4:$D$712,"2021Q2")/SUMIFS(VN_은행채발행!$I$4:$I$712,VN_은행채발행!$D$4:$D$712,"2021Q2",VN_은행채발행!$S$4:$S$712,1),"") | P6: =SUMIFS(월별!$R$5:$R$70,월별!$C$5:$C$70,"2021Q2") -> 0 | Q6: =IFERROR(SUMIFS(VN_은행채발행!$U$4:$U$712,VN_은행채발행!$D$4:$D$712,"2021Q2")/SUMIFS(VN_은행채발행!$Y$4:$Y$712,VN_은행채발행!$D$4:$D$712,"2021Q2"),"") | R6: =IFERROR(SUMIFS(VN_은행채발행!$W$4:$W$712,VN_은행채발행!$D$4:$D$712,"2021Q2")/SUMIFS(VN_은행채발행!$I$4:$I$712,VN_은행채발행!$D$4:$D$712,"2021Q2",VN_은행채발행!$V$4:$V$712,1),"") | S6: =IFERROR(SUMIFS(VN_은행채발행!$X$4:$X$712,VN_은행채발행!$D$4:$D$712,"2021Q2")/SUMIFS(VN_은행채발행!$Z$4:$Z$712,VN_은행채발행!$D$4:$D$712,"2021Q2"),"") | T6: =LOOKUP($B6,정책금리_결정!$J$4:$J$49,정책금리_결정!$K$4:$K$49) -> 0.09 | U6: =IFERROR(AVERAGEIFS(월별!$W$5:$W$70,월별!$C$5:$C$70,"2021Q2"),"") | V6: =IFERROR(AVERAGEIFS(월별!$X$5:$X$70,월별!$C$5:$C$70,"2021Q2"),"") | W6: =IFERROR(AVERAGEIFS(월별!$Y$5:$Y$70,월별!$C$5:$C$70,"2021Q2"),"") -> 0.1056665 | X6: =IFERROR(AVERAGEIFS(월별!$Z$5:$Z$70,월별!$C$5:$C$70,"2021Q2"),"") | Y6: =IFERROR(AVERAGEIFS(월별!$AA$5:$AA$70,월별!$C$5:$C$70,"2021Q2"),"") | Z6: =IFERROR(AVERAGEIFS(월별!$AB$5:$AB$70,월별!$C$5:$C$70,"2021Q2"),"") -> 0.083851347
A7: 2021Q3 | B7: =EOMONTH(DATE(2021,9,1),0) -> 44469 | C7: =LOOKUP($B7,정책금리_결정!$A$4:$A$70,정책금리_결정!$B$4:$B$70) -> -0.001 | D7: =IFERROR(AVERAGEIFS(월별!$F$5:$F$70,월별!$C$5:$C$70,"2021Q3"),"") -> -0.0013179921 | E7: =IFERROR(AVERAGEIFS(월별!$G$5:$G$70,월별!$C$5:$C$70,"2021Q3"),"") -> 0.0010875 | F7: =IFERROR(AVERAGEIFS(월별!$H$5:$H$70,월별!$C$5:$C$70,"2021Q3"),"") -> 0.00068 | G7: =IFERROR(AVERAGEIFS(월별!$I$5:$I$70,월별!$C$5:$C$70,"2021Q3"),"") -> 24.054921 | H7: =LOOKUP($B7,정책금리_결정!$D$4:$D$70,정책금리_결정!$E$4:$E$70) -> 0.0385 | I7: =IFERROR(AVERAGEIFS(월별!$K$5:$K$70,월별!$C$5:$C$70,"2021Q3"),"") -> 0.025919167 | J7: =IFERROR(AVERAGEIFS(월별!$L$5:$L$70,월별!$C$5:$C$70,"2021Q3"),"") -> 0.029660727 | K7: =IFERROR(AVERAGEIFS(월별!$M$5:$M$70,월별!$C$5:$C$70,"2021Q3"),"") -> 0.031301803 | L7: =IFERROR(AVERAGEIFS(월별!$N$5:$N$70,월별!$C$5:$C$70,"2021Q3"),"") -> 37.415606 | M7: =LOOKUP($B7,정책금리_결정!$G$4:$G$9,정책금리_결정!$H$4:$H$9) -> 0.04 | N7: =IFERROR(AVERAGEIFS(월별!$P$5:$P$70,월별!$C$5:$C$70,"2021Q3"),"") -> 0.0071990909 | O7: =IFERROR(SUMIFS(VN_은행채발행!$T$4:$T$712,VN_은행채발행!$D$4:$D$712,"2021Q3")/SUMIFS(VN_은행채발행!$I$4:$I$712,VN_은행채발행!$D$4:$D$712,"2021Q3",VN_은행채발행!$S$4:$S$712,1),"") -> 0.038026964 | P7: =SUMIFS(월별!$R$5:$R$70,월별!$C$5:$C$70,"2021Q3") -> 10 | Q7: =IFERROR(SUMIFS(VN_은행채발행!$U$4:$U$712,VN_은행채발행!$D$4:$D$712,"2021Q3")/SUMIFS(VN_은행채발행!$Y$4:$Y$712,VN_은행채발행!$D$4:$D$712,"2021Q3"),"") -> 314.39144 | R7: =IFERROR(SUMIFS(VN_은행채발행!$W$4:$W$712,VN_은행채발행!$D$4:$D$712,"2021Q3")/SUMIFS(VN_은행채발행!$I$4:$I$712,VN_은행채발행!$D$4:$D$712,"2021Q3",VN_은행채발행!$V$4:$V$712,1),"") | S7: =IFERROR(SUMIFS(VN_은행채발행!$X$4:$X$712,VN_은행채발행!$D$4:$D$712,"2021Q3")/SUMIFS(VN_은행채발행!$Z$4:$Z$712,VN_은행채발행!$D$4:$D$712,"2021Q3"),"") | T7: =LOOKUP($B7,정책금리_결정!$J$4:$J$49,정책금리_결정!$K$4:$K$49) -> 0.095 | U7: =IFERROR(AVERAGEIFS(월별!$W$5:$W$70,월별!$C$5:$C$70,"2021Q3"),"") | V7: =IFERROR(AVERAGEIFS(월별!$X$5:$X$70,월별!$C$5:$C$70,"2021Q3"),"") | W7: =IFERROR(AVERAGEIFS(월별!$Y$5:$Y$70,월별!$C$5:$C$70,"2021Q3"),"") -> 0.10330105 | X7: =IFERROR(AVERAGEIFS(월별!$Z$5:$Z$70,월별!$C$5:$C$70,"2021Q3"),"") | Y7: =IFERROR(AVERAGEIFS(월별!$AA$5:$AA$70,월별!$C$5:$C$70,"2021Q3"),"") | Z7: =IFERROR(AVERAGEIFS(월별!$AB$5:$AB$70,월별!$C$5:$C$70,"2021Q3"),"") -> 0.087903088
A8: 2021Q4 | B8: =EOMONTH(DATE(2021,12,1),0) -> 44561 | C8: =LOOKUP($B8,정책금리_결정!$A$4:$A$70,정책금리_결정!$B$4:$B$70) -> -0.001 | D8: =IFERROR(AVERAGEIFS(월별!$F$5:$F$70,월별!$C$5:$C$70,"2021Q4"),"") -> -0.0011292006 | E8: =IFERROR(AVERAGEIFS(월별!$G$5:$G$70,월별!$C$5:$C$70,"2021Q4"),"") -> 0.0011683333 | F8: =IFERROR(AVERAGEIFS(월별!$H$5:$H$70,월별!$C$5:$C$70,"2021Q4"),"") -> 0.0008775 | G8: =IFERROR(AVERAGEIFS(월별!$I$5:$I$70,월별!$C$5:$C$70,"2021Q4"),"") -> 22.975339 | H8: =LOOKUP($B8,정책금리_결정!$D$4:$D$70,정책금리_결정!$E$4:$E$70) -> 0.038 | I8: =IFERROR(AVERAGEIFS(월별!$K$5:$K$70,월별!$C$5:$C$70,"2021Q4"),"") -> 0.026094217 | J8: =IFERROR(AVERAGEIFS(월별!$L$5:$L$70,월별!$C$5:$C$70,"2021Q4"),"") -> 0.02960443 | K8: =IFERROR(AVERAGEIFS(월별!$M$5:$M$70,월별!$C$5:$C$70,"2021Q4"),"") -> 0.031285489 | L8: =IFERROR(AVERAGEIFS(월별!$N$5:$N$70,월별!$C$5:$C$70,"2021Q4"),"") -> 35.102131 | M8: =LOOKUP($B8,정책금리_결정!$G$4:$G$9,정책금리_결정!$H$4:$H$9) -> 0.04 | N8: =IFERROR(AVERAGEIFS(월별!$P$5:$P$70,월별!$C$5:$C$70,"2021Q4"),"") -> 0.0070391157 | O8: =IFERROR(SUMIFS(VN_은행채발행!$T$4:$T$712,VN_은행채발행!$D$4:$D$712,"2021Q4")/SUMIFS(VN_은행채발행!$I$4:$I$712,VN_은행채발행!$D$4:$D$712,"2021Q4",VN_은행채발행!$S$4:$S$712,1),"") -> 0.032885942 | P8: =SUMIFS(월별!$R$5:$R$70,월별!$C$5:$C$70,"2021Q4") -> 22 | Q8: =IFERROR(SUMIFS(VN_은행채발행!$U$4:$U$712,VN_은행채발행!$D$4:$D$712,"2021Q4")/SUMIFS(VN_은행채발행!$Y$4:$Y$712,VN_은행채발행!$D$4:$D$712,"2021Q4"),"") -> 262.52679 | R8: =IFERROR(SUMIFS(VN_은행채발행!$W$4:$W$712,VN_은행채발행!$D$4:$D$712,"2021Q4")/SUMIFS(VN_은행채발행!$I$4:$I$712,VN_은행채발행!$D$4:$D$712,"2021Q4",VN_은행채발행!$V$4:$V$712,1),"") | S8: =IFERROR(SUMIFS(VN_은행채발행!$X$4:$X$712,VN_은행채발행!$D$4:$D$712,"2021Q4")/SUMIFS(VN_은행채발행!$Z$4:$Z$712,VN_은행채발행!$D$4:$D$712,"2021Q4"),"") | T8: =LOOKUP($B8,정책금리_결정!$J$4:$J$49,정책금리_결정!$K$4:$K$49) -> 0.0975 | U8: =IFERROR(AVERAGEIFS(월별!$W$5:$W$70,월별!$C$5:$C$70,"2021Q4"),"") | V8: =IFERROR(AVERAGEIFS(월별!$X$5:$X$70,월별!$C$5:$C$70,"2021Q4"),"") | W8: =IFERROR(AVERAGEIFS(월별!$Y$5:$Y$70,월별!$C$5:$C$70,"2021Q4"),"") -> 0.10347938 | X8: =IFERROR(AVERAGEIFS(월별!$Z$5:$Z$70,월별!$C$5:$C$70,"2021Q4"),"") | Y8: =IFERROR(AVERAGEIFS(월별!$AA$5:$AA$70,월별!$C$5:$C$70,"2021Q4"),"") | Z8: =IFERROR(AVERAGEIFS(월별!$AB$5:$AB$70,월별!$C$5:$C$70,"2021Q4"),"") -> 0.096303153
A9: 2022Q1 | B9: =EOMONTH(DATE(2022,3,1),0) -> 44651 | C9: =LOOKUP($B9,정책금리_결정!$A$4:$A$70,정책금리_결정!$B$4:$B$70) -> -0.001 | D9: =IFERROR(AVERAGEIFS(월별!$F$5:$F$70,월별!$C$5:$C$70,"2022Q1"),"") -> -0.00034937976 | E9: =IFERROR(AVERAGEIFS(월별!$G$5:$G$70,월별!$C$5:$C$70,"2022Q1"),"") -> 0.0017833333 | F9: =IFERROR(AVERAGEIFS(월별!$H$5:$H$70,월별!$C$5:$C$70,"2022Q1"),"") -> 0.0015183333 | G9: =IFERROR(AVERAGEIFS(월별!$I$5:$I$70,월별!$C$5:$C$70,"2022Q1"),"") -> 21.327131 | H9: =LOOKUP($B9,정책금리_결정!$D$4:$D$70,정책금리_결정!$E$4:$E$70) -> 0.037 | I9: =IFERROR(AVERAGEIFS(월별!$K$5:$K$70,월별!$C$5:$C$70,"2022Q1"),"") -> 0.023461848 | J9: =IFERROR(AVERAGEIFS(월별!$L$5:$L$70,월별!$C$5:$C$70,"2022Q1"),"") -> 0.028132188 | K9: =IFERROR(AVERAGEIFS(월별!$M$5:$M$70,월별!$C$5:$C$70,"2022Q1"),"") -> 0.029271214 | L9: =IFERROR(AVERAGEIFS(월별!$N$5:$N$70,월별!$C$5:$C$70,"2022Q1"),"") -> 46.703401 | M9: =LOOKUP($B9,정책금리_결정!$G$4:$G$9,정책금리_결정!$H$4:$H$9) -> 0.04 | N9: =IFERROR(AVERAGEIFS(월별!$P$5:$P$70,월별!$C$5:$C$70,"2022Q1"),"") -> 0.010780873 | O9: =IFERROR(SUMIFS(VN_은행채발행!$T$4:$T$712,VN_은행채발행!$D$4:$D$712,"2022Q1")/SUMIFS(VN_은행채발행!$I$4:$I$712,VN_은행채발행!$D$4:$D$712,"2022Q1",VN_은행채발행!$S$4:$S$712,1),"") | P9: =SUMIFS(월별!$R$5:$R$70,월별!$C$5:$C$70,"2022Q1") -> 0 | Q9: =IFERROR(SUMIFS(VN_은행채발행!$U$4:$U$712,VN_은행채발행!$D$4:$D$712,"2022Q1")/SUMIFS(VN_은행채발행!$Y$4:$Y$712,VN_은행채발행!$D$4:$D$712,"2022Q1"),"") | R9: =IFERROR(SUMIFS(VN_은행채발행!$W$4:$W$712,VN_은행채발행!$D$4:$D$712,"2022Q1")/SUMIFS(VN_은행채발행!$I$4:$I$712,VN_은행채발행!$D$4:$D$712,"2022Q1",VN_은행채발행!$V$4:$V$712,1),"") | S9: =IFERROR(SUMIFS(VN_은행채발행!$X$4:$X$712,VN_은행채발행!$D$4:$D$712,"2022Q1")/SUMIFS(VN_은행채발행!$Z$4:$Z$712,VN_은행채발행!$D$4:$D$712,"2022Q1"),"") | T9: =LOOKUP($B9,정책금리_결정!$J$4:$J$49,정책금리_결정!$K$4:$K$49) -> 0.135 | U9: =IFERROR(AVERAGEIFS(월별!$W$5:$W$70,월별!$C$5:$C$70,"2022Q1"),"") -> 0.11619286 | V9: =IFERROR(AVERAGEIFS(월별!$X$5:$X$70,월별!$C$5:$C$70,"2022Q1"),"") -> 0.1148825 | W9: =IFERROR(AVERAGEIFS(월별!$Y$5:$Y$70,월별!$C$5:$C$70,"2022Q1"),"") -> 0.10738974 | X9: =IFERROR(AVERAGEIFS(월별!$Z$5:$Z$70,월별!$C$5:$C$70,"2022Q1"),"") | Y9: =IFERROR(AVERAGEIFS(월별!$AA$5:$AA$70,월별!$C$5:$C$70,"2022Q1"),"") -> -53.086466 | Z9: =IFERROR(AVERAGEIFS(월별!$AB$5:$AB$70,월별!$C$5:$C$70,"2022Q1"),"") -> 0.11793993
A10: 2022Q2 | B10: =EOMONTH(DATE(2022,6,1),0) -> 44742 | C10: =LOOKUP($B10,정책금리_결정!$A$4:$A$70,정책금리_결정!$B$4:$B$70) -> -0.001 | D10: =IFERROR(AVERAGEIFS(월별!$F$5:$F$70,월별!$C$5:$C$70,"2022Q2"),"") -> -0.00043414673 | E10: =IFERROR(AVERAGEIFS(월별!$G$5:$G$70,월별!$C$5:$C$70,"2022Q2"),"") -> 0.0018858333 | F10: =IFERROR(AVERAGEIFS(월별!$H$5:$H$70,월별!$C$5:$C$70,"2022Q2"),"") -> 0.0016508333 | G10: =IFERROR(AVERAGEIFS(월별!$I$5:$I$70,월별!$C$5:$C$70,"2022Q2"),"") -> 23.199801 | H10: =LOOKUP($B10,정책금리_결정!$D$4:$D$70,정책금리_결정!$E$4:$E$70) -> 0.037 | I10: =IFERROR(AVERAGEIFS(월별!$K$5:$K$70,월별!$C$5:$C$70,"2022Q2"),"") -> 0.023811694 | J10: =IFERROR(AVERAGEIFS(월별!$L$5:$L$70,월별!$C$5:$C$70,"2022Q2"),"") -> 0.02799689 | K10: =IFERROR(AVERAGEIFS(월별!$M$5:$M$70,월별!$C$5:$C$70,"2022Q2"),"") -> 0.029263706 | L10: =IFERROR(AVERAGEIFS(월별!$N$5:$N$70,월별!$C$5:$C$70,"2022Q2"),"") -> 41.85196 | M10: =LOOKUP($B10,정책금리_결정!$G$4:$G$9,정책금리_결정!$H$4:$H$9) -> 0.04 | N10: =IFERROR(AVERAGEIFS(월별!$P$5:$P$70,월별!$C$5:$C$70,"2022Q2"),"") -> 0.021991861 | O10: =IFERROR(SUMIFS(VN_은행채발행!$T$4:$T$712,VN_은행채발행!$D$4:$D$712,"2022Q2")/SUMIFS(VN_은행채발행!$I$4:$I$712,VN_은행채발행!$D$4:$D$712,"2022Q2",VN_은행채발행!$S$4:$S$712,1),"") -> 0.043337838 | P10: =SUMIFS(월별!$R$5:$R$70,월별!$C$5:$C$70,"2022Q2") -> 8 | Q10: =IFERROR(SUMIFS(VN_은행채발행!$U$4:$U$712,VN_은행채발행!$D$4:$D$712,"2022Q2")/SUMIFS(VN_은행채발행!$Y$4:$Y$712,VN_은행채발행!$D$4:$D$712,"2022Q2"),"") -> 201.85 | R10: =IFERROR(SUMIFS(VN_은행채발행!$W$4:$W$712,VN_은행채발행!$D$4:$D$712,"2022Q2")/SUMIFS(VN_은행채발행!$I$4:$I$712,VN_은행채발행!$D$4:$D$712,"2022Q2",VN_은행채발행!$V$4:$V$712,1),"") -> 0.068 | S10: =IFERROR(SUMIFS(VN_은행채발행!$X$4:$X$712,VN_은행채발행!$D$4:$D$712,"2022Q2")/SUMIFS(VN_은행채발행!$Z$4:$Z$712,VN_은행채발행!$D$4:$D$712,"2022Q2"),"") | T10: =LOOKUP($B10,정책금리_결정!$J$4:$J$49,정책금리_결정!$K$4:$K$49) -> 0.14 | U10: =IFERROR(AVERAGEIFS(월별!$W$5:$W$70,월별!$C$5:$C$70,"2022Q2"),"") -> 0.13399356 | V10: =IFERROR(AVERAGEIFS(월별!$X$5:$X$70,월별!$C$5:$C$70,"2022Q2"),"") -> 0.12040408 | W10: =IFERROR(AVERAGEIFS(월별!$Y$5:$Y$70,월별!$C$5:$C$70,"2022Q2"),"") -> 0.11349628 | X10: =IFERROR(AVERAGEIFS(월별!$Z$5:$Z$70,월별!$C$5:$C$70,"2022Q2"),"") | Y10: =IFERROR(AVERAGEIFS(월별!$AA$5:$AA$70,월별!$C$5:$C$70,"2022Q2"),"") -> -204.97281 | Z10: =IFERROR(AVERAGEIFS(월별!$AB$5:$AB$70,월별!$C$5:$C$70,"2022Q2"),"") -> 0.1389621
A11: 2022Q3 | B11: =EOMONTH(DATE(2022,9,1),0) -> 44834 | C11: =LOOKUP($B11,정책금리_결정!$A$4:$A$70,정책금리_결정!$B$4:$B$70) -> -0.001 | D11: =IFERROR(AVERAGEIFS(월별!$F$5:$F$70,월별!$C$5:$C$70,"2022Q3"),"") -> -0.00076269697 | E11: =IFERROR(AVERAGEIFS(월별!$G$5:$G$70,월별!$C$5:$C$70,"2022Q3"),"") -> 0.0020502778 | F11: =IFERROR(AVERAGEIFS(월별!$H$5:$H$70,월별!$C$5:$C$70,"2022Q3"),"") -> 0.0016047222 | G11: =IFERROR(AVERAGEIFS(월별!$I$5:$I$70,월별!$C$5:$C$70,"2022Q3"),"") -> 28.129747 | H11: =LOOKUP($B11,정책금리_결정!$D$4:$D$70,정책금리_결정!$E$4:$E$70) -> 0.0365 | I11: =IFERROR(AVERAGEIFS(월별!$K$5:$K$70,월별!$C$5:$C$70,"2022Q3"),"") -> 0.02302633 | J11: =IFERROR(AVERAGEIFS(월별!$L$5:$L$70,월별!$C$5:$C$70,"2022Q3"),"") -> 0.025862475 | K11: =IFERROR(AVERAGEIFS(월별!$M$5:$M$70,월별!$C$5:$C$70,"2022Q3"),"") -> 0.026794812 | L11: =IFERROR(AVERAGEIFS(월별!$N$5:$N$70,월별!$C$5:$C$70,"2022Q3"),"") -> 28.361449 | M11: =LOOKUP($B11,정책금리_결정!$G$4:$G$9,정책금리_결정!$H$4:$H$9) -> 0.05 | N11: =IFERROR(AVERAGEIFS(월별!$P$5:$P$70,월별!$C$5:$C$70,"2022Q3"),"") -> 0.031734241 | O11: =IFERROR(SUMIFS(VN_은행채발행!$T$4:$T$712,VN_은행채발행!$D$4:$D$712,"2022Q3")/SUMIFS(VN_은행채발행!$I$4:$I$712,VN_은행채발행!$D$4:$D$712,"2022Q3",VN_은행채발행!$S$4:$S$712,1),"") | P11: =SUMIFS(월별!$R$5:$R$70,월별!$C$5:$C$70,"2022Q3") -> 0 | Q11: =IFERROR(SUMIFS(VN_은행채발행!$U$4:$U$712,VN_은행채발행!$D$4:$D$712,"2022Q3")/SUMIFS(VN_은행채발행!$Y$4:$Y$712,VN_은행채발행!$D$4:$D$712,"2022Q3"),"") | R11: =IFERROR(SUMIFS(VN_은행채발행!$W$4:$W$712,VN_은행채발행!$D$4:$D$712,"2022Q3")/SUMIFS(VN_은행채발행!$I$4:$I$712,VN_은행채발행!$D$4:$D$712,"2022Q3",VN_은행채발행!$V$4:$V$712,1),"") | S11: =IFERROR(SUMIFS(VN_은행채발행!$X$4:$X$712,VN_은행채발행!$D$4:$D$712,"2022Q3")/SUMIFS(VN_은행채발행!$Z$4:$Z$712,VN_은행채발행!$D$4:$D$712,"2022Q3"),"") | T11: =LOOKUP($B11,정책금리_결정!$J$4:$J$49,정책금리_결정!$K$4:$K$49) -> 0.145 | U11: =IFERROR(AVERAGEIFS(월별!$W$5:$W$70,월별!$C$5:$C$70,"2022Q3"),"") -> 0.12949591 | V11: =IFERROR(AVERAGEIFS(월별!$X$5:$X$70,월별!$C$5:$C$70,"2022Q3"),"") -> 0.13459005 | W11: =IFERROR(AVERAGEIFS(월별!$Y$5:$Y$70,월별!$C$5:$C$70,"2022Q3"),"") -> 0.11713197 | X11: =IFERROR(AVERAGEIFS(월별!$Z$5:$Z$70,월별!$C$5:$C$70,"2022Q3"),"") | Y11: =IFERROR(AVERAGEIFS(월별!$AA$5:$AA$70,월별!$C$5:$C$70,"2022Q3"),"") -> -123.63939 | Z11: =IFERROR(AVERAGEIFS(월별!$AB$5:$AB$70,월별!$C$5:$C$70,"2022Q3"),"") -> 0.13779712
A12: 2022Q4 | B12: =EOMONTH(DATE(2022,12,1),0) -> 44926 | C12: =LOOKUP($B12,정책금리_결정!$A$4:$A$70,정책금리_결정!$B$4:$B$70) -> -0.001 | D12: =IFERROR(AVERAGEIFS(월별!$F$5:$F$70,월별!$C$5:$C$70,"2022Q4"),"") -> -0.00014775758 | E12: =IFERROR(AVERAGEIFS(월별!$G$5:$G$70,월별!$C$5:$C$70,"2022Q4"),"") -> 0.0028233333 | F12: =IFERROR(AVERAGEIFS(월별!$H$5:$H$70,월별!$C$5:$C$70,"2022Q4"),"") -> 0.0023233333 | G12: =IFERROR(AVERAGEIFS(월별!$I$5:$I$70,월별!$C$5:$C$70,"2022Q4"),"") -> 29.710909 | H12: =LOOKUP($B12,정책금리_결정!$D$4:$D$70,정책금리_결정!$E$4:$E$70) -> 0.0365 | I12: =IFERROR(AVERAGEIFS(월별!$K$5:$K$70,월별!$C$5:$C$70,"2022Q4"),"") -> 0.023822989 | J12: =IFERROR(AVERAGEIFS(월별!$L$5:$L$70,월별!$C$5:$C$70,"2022Q4"),"") -> 0.026916721 | K12: =IFERROR(AVERAGEIFS(월별!$M$5:$M$70,월별!$C$5:$C$70,"2022Q4"),"") -> 0.029157914 | L12: =IFERROR(AVERAGEIFS(월별!$N$5:$N$70,월별!$C$5:$C$70,"2022Q4"),"") -> 30.937319 | M12: =LOOKUP($B12,정책금리_결정!$G$4:$G$9,정책금리_결정!$H$4:$H$9) -> 0.06 | N12: =IFERROR(AVERAGEIFS(월별!$P$5:$P$70,월별!$C$5:$C$70,"2022Q4"),"") -> 0.049766053 | O12: =IFERROR(SUMIFS(VN_은행채발행!$T$4:$T$712,VN_은행채발행!$D$4:$D$712,"2022Q4")/SUMIFS(VN_은행채발행!$I$4:$I$712,VN_은행채발행!$D$4:$D$712,"2022Q4",VN_은행채발행!$S$4:$S$712,1),"") | P12: =SUMIFS(월별!$R$5:$R$70,월별!$C$5:$C$70,"2022Q4") -> 0 | Q12: =IFERROR(SUMIFS(VN_은행채발행!$U$4:$U$712,VN_은행채발행!$D$4:$D$712,"2022Q4")/SUMIFS(VN_은행채발행!$Y$4:$Y$712,VN_은행채발행!$D$4:$D$712,"2022Q4"),"") | R12: =IFERROR(SUMIFS(VN_은행채발행!$W$4:$W$712,VN_은행채발행!$D$4:$D$712,"2022Q4")/SUMIFS(VN_은행채발행!$I$4:$I$712,VN_은행채발행!$D$4:$D$712,"2022Q4",VN_은행채발행!$V$4:$V$712,1),"") | S12: =IFERROR(SUMIFS(VN_은행채발행!$X$4:$X$712,VN_은행채발행!$D$4:$D$712,"2022Q4")/SUMIFS(VN_은행채발행!$Z$4:$Z$712,VN_은행채발행!$D$4:$D$712,"2022Q4"),"") | T12: =LOOKUP($B12,정책금리_결정!$J$4:$J$49,정책금리_결정!$K$4:$K$49) -> 0.1675 | U12: =IFERROR(AVERAGEIFS(월별!$W$5:$W$70,월별!$C$5:$C$70,"2022Q4"),"") -> 0.12945061 | V12: =IFERROR(AVERAGEIFS(월별!$X$5:$X$70,월별!$C$5:$C$70,"2022Q4"),"") -> 0.14815622 | W12: =IFERROR(AVERAGEIFS(월별!$Y$5:$Y$70,월별!$C$5:$C$70,"2022Q4"),"") -> 0.12341608 | X12: =IFERROR(AVERAGEIFS(월별!$Z$5:$Z$70,월별!$C$5:$C$70,"2022Q4"),"") | Y12: =IFERROR(AVERAGEIFS(월별!$AA$5:$AA$70,월별!$C$5:$C$70,"2022Q4"),"") -> -60.34531 | Z12: =IFERROR(AVERAGEIFS(월별!$AB$5:$AB$70,월별!$C$5:$C$70,"2022Q4"),"") -> 0.15446159
A13: 2023Q1 | B13: =EOMONTH(DATE(2023,3,1),0) -> 45016 | C13: =LOOKUP($B13,정책금리_결정!$A$4:$A$70,정책금리_결정!$B$4:$B$70) -> -0.001 | D13: =IFERROR(AVERAGEIFS(월별!$F$5:$F$70,월별!$C$5:$C$70,"2023Q1"),"") -> 8.460925e-06 | E13: =IFERROR(AVERAGEIFS(월별!$G$5:$G$70,월별!$C$5:$C$70,"2023Q1"),"") -> 0.00359 | F13: =IFERROR(AVERAGEIFS(월별!$H$5:$H$70,월별!$C$5:$C$70,"2023Q1"),"") -> 0.0028466667 | G13: =IFERROR(AVERAGEIFS(월별!$I$5:$I$70,월별!$C$5:$C$70,"2023Q1"),"") -> 35.815391 | H13: =LOOKUP($B13,정책금리_결정!$D$4:$D$70,정책금리_결정!$E$4:$E$70) -> 0.0365 | I13: =IFERROR(AVERAGEIFS(월별!$K$5:$K$70,월별!$C$5:$C$70,"2023Q1"),"") -> 0.025266568 | J13: =IFERROR(AVERAGEIFS(월별!$L$5:$L$70,월별!$C$5:$C$70,"2023Q1"),"") -> 0.02887289 | K13: =IFERROR(AVERAGEIFS(월별!$M$5:$M$70,월별!$C$5:$C$70,"2023Q1"),"") -> 0.031482398 | L13: =IFERROR(AVERAGEIFS(월별!$N$5:$N$70,월별!$C$5:$C$70,"2023Q1"),"") -> 36.063213 | M13: =LOOKUP($B13,정책금리_결정!$G$4:$G$9,정책금리_결정!$H$4:$H$9) -> 0.06 | N13: =IFERROR(AVERAGEIFS(월별!$P$5:$P$70,월별!$C$5:$C$70,"2023Q1"),"") -> 0.041367628 | O13: =IFERROR(SUMIFS(VN_은행채발행!$T$4:$T$712,VN_은행채발행!$D$4:$D$712,"2023Q1")/SUMIFS(VN_은행채발행!$I$4:$I$712,VN_은행채발행!$D$4:$D$712,"2023Q1",VN_은행채발행!$S$4:$S$712,1),"") | P13: =SUMIFS(월별!$R$5:$R$70,월별!$C$5:$C$70,"2023Q1") -> 0 | Q13: =IFERROR(SUMIFS(VN_은행채발행!$U$4:$U$712,VN_은행채발행!$D$4:$D$712,"2023Q1")/SUMIFS(VN_은행채발행!$Y$4:$Y$712,VN_은행채발행!$D$4:$D$712,"2023Q1"),"") | R13: =IFERROR(SUMIFS(VN_은행채발행!$W$4:$W$712,VN_은행채발행!$D$4:$D$712,"2023Q1")/SUMIFS(VN_은행채발행!$I$4:$I$712,VN_은행채발행!$D$4:$D$712,"2023Q1",VN_은행채발행!$V$4:$V$712,1),"") | S13: =IFERROR(SUMIFS(VN_은행채발행!$X$4:$X$712,VN_은행채발행!$D$4:$D$712,"2023Q1")/SUMIFS(VN_은행채발행!$Z$4:$Z$712,VN_은행채발행!$D$4:$D$712,"2023Q1"),"") | T13: =LOOKUP($B13,정책금리_결정!$J$4:$J$49,정책금리_결정!$K$4:$K$49) -> 0.1675 | U13: =IFERROR(AVERAGEIFS(월별!$W$5:$W$70,월별!$C$5:$C$70,"2023Q1"),"") -> 0.1378057 | V13: =IFERROR(AVERAGEIFS(월별!$X$5:$X$70,월별!$C$5:$C$70,"2023Q1"),"") -> 0.15844224 | W13: =IFERROR(AVERAGEIFS(월별!$Y$5:$Y$70,월별!$C$5:$C$70,"2023Q1"),"") -> 0.13149614 | X13: =IFERROR(AVERAGEIFS(월별!$Z$5:$Z$70,월별!$C$5:$C$70,"2023Q1"),"") | Y13: =IFERROR(AVERAGEIFS(월별!$AA$5:$AA$70,월별!$C$5:$C$70,"2023Q1"),"") -> -63.095614 | Z13: =IFERROR(AVERAGEIFS(월별!$AB$5:$AB$70,월별!$C$5:$C$70,"2023Q1"),"") -> 0.16174158
